Workbook
Name curve_IDs: [1]CurveCodes!$B$10:INDEX([1]CurveCodes!$B$10:$B$5000, COUNTA([1]CurveCodes!$C$10:$C$5000))
Name frequencies: [1]Filters!$B$10:$B$15
Name months: [1]Filters!$C$10:$C$29
Name quarters: [1]Filters!$D$10:$D$18
Name selected_frequency_relative: [1]Results!$C$18
Name weeks: [1]Filters!$F$10:$F$17
Name years: [1]Filters!$E$10:$E$13

Sheet Modelling Architecture
B2: 1. OSP modelling summary table
B4: Dimension | C4: Arab Light model | D4: Arab Medium model | E4: Arab Extra Light model
B5: Target variable | C5: Δ Arab Light OSP | D5: Δ (Arab Medium – Arab Light OSP) | E5: Δ (Arab XLT – Arab Light OSP)
B6: Pricing logic | C6: Benchmark-driven | D6: Relative grade differential | E6: Relative grade differential
B7: Model type | C7: Deterministic / rule-based | D7: Ridge regression | E7: Ridge regression
B8: Estimation frequency | C8: Monthly | D8: Monthly | E8: Monthly
B9: Estimation timing | C9: Run on 2nd of month t | D9: Run on 2nd of month t | E9: Run on 2nd of month t
B10: OSP release targeted | C10: OSP announced ~5th of month t | D10: Same OSP cycle | E10: Same OSP cycle
B11: Lookback window (data) | C11: Monthly (since Jan 2022) | D11: Monthly (since Jan 2020) | E11: Monthly (since Jan 2020)
B12: OOS horizon | C12: Real-time (1 month ahead) | D12: Real-time (1 month ahead) | E12: Real-time (1 month ahead)
B13: Core benchmark | C13: Dubai Mo01 & Mo03 | D13: Dubai/Oman-linked grades | E13: Murban/Dubai
B14: Key transformation | C14: Dubai cash premium (Mo01 – Mo03) | D14: Predicted level diff → Δ | E14: Predicted level diff → Δ
B16: 2. Inputs by model (what must be updated monthly)
B18: Model | C18: Input | D18: Frequency | E18: Notes | F18: Lag
B19: Arab Light | C19: Dubai Mo01 | D19: Daily | E19: Platts daily | F19: L0
B20: Arab Light | C20: Dubai Mo03 | D20: Daily | E20: Platts daily | F20: L0
B21: Arab Light | C21: Dubai cash premium | D21: Derived | E21: Mo01 – Mo03 | F21: L0
B22: Arab Light | C22: Monthly average window | D22: Rule | E22: Avg from 5th (t−1) to 2nd (t) | F22: L0
B23: Arab Light | C23: Signal used | D23: Δ monthly avg cash premium | E23: Current vs previous window | F23: L0
B24: Arab Med-light diff | C24: ArabMed–ArabLight (t−1) | D24: Monthly | E24: Level updated each run | F24: L0
B25: Arab Med-light diff | C25: Qatar Marine FOB | D25: Monthly | E25: Medium-sour proxy | F25: L1
B26: Arab Med-light diff | C26: Asia runs | D26: Monthly | E26: From agencies | F26: L0
B27: Arab Med-light diff | C27: ASL/AL export ratio | D27: Monthly | E27: Structural | F27: L2
B28: Arab Med-light diff | C28: AXL/AL export ratio | D28: Monthly | E28: Structural | F28: L2
B29: Arab Med-light diff | C29: AM/AL export ratio | D29: Monthly | E29: Structural | F29: L2
... B40: Arab xlt-light diff | C40: AH/AL export ratio | D40: Monthly | E40: Structural | F40: L2
B42: 3. Performance Comparison
B44: Metric | C44: Arab Light | D44: Arab Medium | E44: Arab Extra Light
B45: Historical correlation | C45: 0.968 | D45: ~80% (OOS) | E45: ~74% (OOS)
B46: Sign hit rate | C46: 0.8 | D46: ~63% | E46: ~54%
B47: Model risk | C47: Very low | D47: Medium | E47: Medium–high
B48: Economic transparency | C48: Very high | D48: High | E48: High
B49: Sensitivity to admin decisions | C49: Low | D49: Medium | E49: High
B50: Engine | C50: Engine 1: deterministic | D50: Engine 2: ridge | E50: Engine 3: ridge

Sheet Arablight OSP
A1: Description | B1: Dubai Mo01 (NextGen MOC) | C1: Dubai Mo03 | D1: Dubai cash premium | E1: Monthly average of Dubai cash premium | F1: Projected change in OSP | J1: TimeStamp | K1: Value | L1: Change in OSP | M1: Predicted change in OSP (before announcement) | N1: Hit Flag | O1: Hit Rate | P1: Correlation
A2: Currency/UOM | B2: USD/bbl | C2: USD/bbl | D2: ( Mo01-Mo03) | E2: (from previous announcement until last data point) | F2: (difference between current and previous monthly averages) | J2: 46082 | K2: =+K3+M2 -> -0.53615789 | M2: =+F5 -> -0.83615789 | N2: =+IF(SIGN(L2)=SIGN(M2),1,0) -> 0 | O2: =+SUM(N3:N52)/COUNT(N3:N52) -> 0.8 | P2: =+CORREL(M3:M52,L3:L52) -> 0.96667772
A3: Symbol Code | B3: PCAAT00 | C3: PCAAV00 | J3: 46054 | K3: 0.3 | L3: =+K3-K4 -> -0.3 | M3: =+F25 -> -0.20252392 | N3: =+IF(SIGN(L3)=SIGN(M3),1,0) -> 1
A4: Bate | B4: Close | C4: Close | J4: 46023 | K4: 0.6 | L4: =+K4-K5 -> -0.4 | M4: =+F47 -> -0.60690191 | N4: =+IF(SIGN(L4)=SIGN(M4),1,0) -> 1
A5: 46052 | B5: 66.54 | C5: 66.85 | D5: =+B5-C5 -> -0.31 | E5: =+AVERAGE(D5:D24) -> -0.253 | F5: =+E5-E25 -> -0.83615789 | J5: 45992 | K5: 1 | L5: =+K5-K6 -> -1.2 | M5: =+F69 -> -1.2704444 | N5: =+IF(SIGN(L5)=SIGN(M5),1,0) -> 1
A6: 46051 | B6: 66.35 | C6: 66.52 | D6: =+B6-C6 -> -0.17 | J6: 45962 | K6: 2.2 | L6: =+K6-K7 -> 0 | M6: =+F88 -> 0.078619048 | N6: =+IF(SIGN(L6)=SIGN(M6),1,0) -> 0
A7: 46050 | B7: 64.66 | C7: 64.84 | D7: =+B7-C7 -> -0.18 | J7: 45931 | K7: 2.2 | L7: =+K7-K8 -> -1 | M7: =+F110 -> -0.49911905 | N7: =+IF(SIGN(L7)=SIGN(M7),1,0) -> 1
A8: 46049 | B8: 62.88 | C8: 62.92 | D8: =+B8-C8 -> -0.04 | J8: 45901 | K8: 3.2 | L8: =+K8-K9 -> 1 | M8: =+F132 -> 0.79775 | N8: =+IF(SIGN(L8)=SIGN(M8),1,0) -> 1
A9: 46048 | B9: 63.555 | C9: 63.69 | D9: =+B9-C9 -> -0.135 | J9: 45870 | K9: 2.2 | L9: =+K9-K10 -> 1 | M9: =+F154 -> 0.869 | N9: =+IF(SIGN(L9)=SIGN(M9),1,0) -> 1
A10: 46045 | B10: 62.27 | C10: 62.61 | D10: =+B10-C10 -> -0.34 | J10: 45839 | K10: 1.2 | L10: =+K10-K11 -> -0.2 | M10: =+F176 -> -0.15608333 | N10: =+IF(SIGN(L10)=SIGN(M10),1,0) -> 1
A11: 46044 | B11: 63.21 | C11: 63.46 | D11: =+B11-C11 -> -0.25 | J11: 45809 | K11: 1.4 | L11: =+K11-K12 -> 0.2 | M11: =+F196 -> -0.061166667 | N11: =+IF(SIGN(L11)=SIGN(M11),1,0) -> 0
A12: 46043 | B12: 62.34 | C12: 62.58 | D12: =+B12-C12 -> -0.24 | J12: 45778 | K12: 1.2 | L12: =+K12-K13 -> -2.3 | M12: =+F216 -> -1.7691111 | N12: =+IF(SIGN(L12)=SIGN(M12),1,0) -> 1
A13: 46042 | B13: 61.8 | C13: 61.84 | D13: =+B13-C13 -> -0.04 | J13: 45748 | K13: 3.5 | L13: =+K13-K14 -> -0.4 | M13: =+F238 -> -0.32415205 | N13: =+IF(SIGN(L13)=SIGN(M13),1,0) -> 1
A14: 46041 | B14: 61.95 | C14: 62 | D14: =+B14-C14 -> -0.05 | J14: 45717 | K14: 3.9 | L14: =+K14-K15 -> 2.4 | M14: =+F257 -> 2.4334211 | N14: =+IF(SIGN(L14)=SIGN(M14),1,0) -> 1
A15: 46038 | B15: 62.28 | C15: 62.27 | D15: =+B15-C15 -> 0.01 | J15: 45689 | K15: 1.5 | L15: =+K15-K16 -> 0.6 | M15: =+F277 -> 0.47959211 | N15: =+IF(SIGN(L15)=SIGN(M15),1,0) -> 1
A16: 46037 | B16: 62.55 | C16: 62.69 | D16: =+B16-C16 -> -0.14 | J16: 45658 | K16: 0.9 | L16: =+K16-K17 -> -0.8 | M16: =+F298 -> -0.83590789 | N16: =+IF(SIGN(L16)=SIGN(M16),1,0) -> 1
A17: 46036 | B17: 62.41 | C17: 62.76 | D17: =+B17-C17 -> -0.35 | J17: 45627 | K17: 1.7 | L17: =+K17-K18 -> -0.5 | M17: =+F319 -> -0.46584211 | N17: =+IF(SIGN(L17)=SIGN(M17),1,0) -> 1
A18: 46035 | B18: 61.76 | C18: 62.14 | D18: =+B18-C18 -> -0.38 | J18: 45597 | K18: 2.2 | L18: =+K18-K19 -> 0.9 | M18: =+F340 -> 0.996 | N18: =+IF(SIGN(L18)=SIGN(M18),1,0) -> 1
A19: 46034 | B19: 61.405 | C19: 61.68 | D19: =+B19-C19 -> -0.275 | J19: 45566 | K19: 1.3 | L19: =+K19-K20 -> -0.7 | M19: =+F362 -> -0.53604762 | N19: =+IF(SIGN(L19)=SIGN(M19),1,0) -> 1
A20: 46031 | B20: 60.8 | C20: 61.08 | D20: =+B20-C20 -> -0.28 | J20: 45536 | K20: 2 | L20: =+K20-K21 -> 0.2 | M20: =+F382 -> 0.59615288 | N20: =+IF(SIGN(L20)=SIGN(M20),1,0) -> 1
A21: 46030 | B21: 58.32 | C21: 58.77 | D21: =+B21-C21 -> -0.45 | J21: 45505 | K21: 1.8 | L21: =+K21-K22 -> -0.6 | M21: =+F405 -> -0.74552632 | N21: =+IF(SIGN(L21)=SIGN(M21),1,0) -> 1
A22: 46029 | B22: 58.3 | C22: 58.85 | D22: =+B22-C22 -> -0.55 | J22: 45474 | K22: 2.4 | L22: =+K22-K23 -> -0.5 | M22: =+F426 -> -0.43519006 | N22: =+IF(SIGN(L22)=SIGN(M22),1,0) -> 1
A23: 46028 | B23: 59.4 | C23: 59.98 | D23: =+B23-C23 -> -0.58 | J23: 45444 | K23: 2.9 | L23: =+K23-K24 -> 0.9 | M23: =+F446 -> 0.73386111 | N23: =+IF(SIGN(L23)=SIGN(M23),1,0) -> 1
A24: 46027 | B24: 58.25 | C24: 58.56 | D24: =+B24-C24 -> -0.31 | J24: 45413 | K24: 2 | L24: =+K24-K25 -> 0.3 | M24: =+F466 -> 0.31685526 | N24: =+IF(SIGN(L24)=SIGN(M24),1,0) -> 1
A25: 46024 | B25: 60.31 | C25: 60.41 | D25: =+B25-C25 -> -0.1 | E25: =+AVERAGE(D25:D43) -> 0.58315789 | F25: =+E25-E44 -> -0.20252392 | J25: 45383 | K25: 1.7 | L25: =+K25-K26 -> 0.2 | M25: =+SUMIFS($F$92:$F$1029,$A$92:$A$1029,$J26) -> 0.022894737 | N25: =+IF(SIGN(L25)=SIGN(M25),1,0) -> 1
A26: 46022 | B26: 61.57 | C26: 61.13 | D26: =+B26-C26 -> 0.44 | J26: 45352 | K26: 1.5 | L26: =+K26-K27 -> 0 | M26: =+F506 -> 0.85078947 | N26: =+IF(SIGN(L26)=SIGN(M26),1,0) -> 0
A27: 46021 | B27: 61.73 | C27: 61.01 | D27: =+B27-C27 -> 0.72 | J27: 45323 | K27: 1.5 | L27: =+K27-K28 -> -2 | M27: =+F529 -> -1.5 | N27: =+IF(SIGN(L27)=SIGN(M27),1,0) -> 1
A28: 46020 | B28: 61.25 | C28: 60.49 | D28: =+B28-C28 -> 0.76 | J28: 45292 | K28: 3.5 | L28: =+K28-K29 -> -0.5 | M28: =+SUMIFS($F$92:$F$1029,$A$92:$A$1029,$J29) -> -0.77269424 | N28: =+IF(SIGN(L28)=SIGN(M28),1,0) -> 1
A29: 46017 | B29: 62.22 | C29: 61.49 | D29: =+B29-C29 -> 0.73 | J29: 45261 | K29: 4 | L29: =+K29-K30 -> 0 | M29: =+F569 -> -0.20784524 | N29: =+IF(SIGN(L29)=SIGN(M29),1,0) -> 0
A30: 46015 | B30: 62.35 | C30: 61.4 | D30: =+B30-C30 -> 0.95 | J30: 45231 | K30: 4 | L30: =+K30-K31 -> 0.4 | M30: =+F592 -> 0.70308333 | N30: =+IF(SIGN(L30)=SIGN(M30),1,0) -> 1
A31: 46014 | B31: 62.15 | C31: 61.44 | D31: =+B31-C31 -> 0.71 | J31: 45200 | K31: 3.6 | L31: =+K31-K32 -> 0.1 | M31: =+F613 -> 0.34214286 | N31: =+IF(SIGN(L31)=SIGN(M31),1,0) -> 1
A32: 46013 | B32: 61.2 | C32: 60.63 | D32: =+B32-C32 -> 0.57 | J32: 45170 | K32: 3.5 | L32: =+K32-K33 -> 0.3 | M32: =+F633 -> 0.49847118 | N32: =+IF(SIGN(L32)=SIGN(M32),1,0) -> 1
A33: 46010 | B33: 60.01 | C33: 59.45 | D33: =+B33-C33 -> 0.56 | J33: 45139 | K33: 3.2 | L33: =+K33-K34 -> 0.2 | M33: =+F656 -> 0.16830263 | N33: =+IF(SIGN(L33)=SIGN(M33),1,0) -> 1
A34: 46009 | B34: 60.32 | C34: 59.75 | D34: =+B34-C34 -> 0.57 | J34: 45108 | K34: 3 | L34: =+K34-K35 -> 0.45 | M34: =+SUMIFS($F$92:$F$1029,$A$92:$A$1029,$J35) -> -0.72669444 | N34: =+IF(SIGN(L34)=SIGN(M34),1,0) -> 0
A35: 46008 | B35: 59.72 | C35: 59.25 | D35: =+B35-C35 -> 0.47 | J35: 45078 | K35: 2.55 | L35: =+K35-K36 -> -0.25 | M35: =+F697 -> 0.14694444 | N35: =+IF(SIGN(L35)=SIGN(M35),1,0) -> 0
A36: 46007 | B36: 59.93 | C36: 59.61 | D36: =+B36-C36 -> 0.32 | J36: 45047 | K36: 2.8 | L36: =+K36-K37 -> 0.3 | M36: =+F717 -> -0.59776316 | N36: =+IF(SIGN(L36)=SIGN(M36),1,0) -> 0
A37: 46006 | B37: 61.25 | C37: 60.73 | D37: =+B37-C37 -> 0.52 | J37: 45017 | K37: 2.5 | L37: =+K37-K38 -> 0.5 | M37: =+F738 -> 0.99184211 | N37: =+IF(SIGN(L37)=SIGN(M37),1,0) -> 1
A38: 46003 | B38: 61.75 | C38: 61.24 | D38: =+B38-C38 -> 0.51 | J38: 44986 | K38: 2 | L38: =+K38-K39 -> 0.2 | M38: =+F758 -> -0.15421053 | N38: =+IF(SIGN(L38)=SIGN(M38),1,0) -> 0
A39: 46002 | B39: 61.57 | C39: 61.11 | D39: =+B39-C39 -> 0.46 | J39: 44958 | K39: 1.8 | L39: =+K39-K40 -> -1.45 | M39: =+F779 -> -1.1431184 | N39: =+IF(SIGN(L39)=SIGN(M39),1,0) -> 1
A40: 46001 | B40: 62.19 | C40: 61.53 | D40: =+B40-C40 -> 0.66 | J40: 44927 | K40: 3.25 | L40: =+K40-K41 -> -2.2 | M40: =+F798 -> -2.27875 | N40: =+IF(SIGN(L40)=SIGN(M40),1,0) -> 1
...

Sheet Arabmedlight
A1: Date | B1: Arabmed_lt_diff_L0 | C1: Qatar Marine FOB Qatar_L1 | D1: Asia Runs_L0 | E1: ASL/AL_L2 | F1: AXL/AL_L2 | G1: AM/AL_L2 | H1: AH/AL_L2 | I1: Dubai-ALT asia margins L1 | J1: HCU_BVU_HSFO_L1 (1-4)
A2: 43831 | B2: -1.65 | D2: =+SUMIFS('Runs - Platts'!$B$2:$B$97,'Runs - Platts'!$G$2:$G$97,$A2) -> 31286.883
A3: 43862 | B3: -1.25 | D3: =+SUMIFS('Runs - Platts'!$B$2:$B$97,'Runs - Platts'!$G$2:$G$97,$A3) -> 27448.856 | J3: -249.325
A4: 43891 | B4: -0.95 | D4: =+SUMIFS('Runs - Platts'!$B$2:$B$97,'Runs - Platts'!$G$2:$G$97,$A4) -> 28237.405 | E4: 0.017631421 | F4: 0.16944608 | G4: 0.30905932 | H4: 0.33766228 | J4: -215.755
A5: 43922 | B5: -0.95 | D5: =+SUMIFS('Runs - Platts'!$B$2:$B$97,'Runs - Platts'!$G$2:$G$97,$A5) -> 27243.656 | E5: 0.019898142 | F5: 0.26549393 | G5: 0.29969384 | H5: 0.31088288 | J5: -218.52667
A6: 43952 | B6: -0.1 | D6: =+SUMIFS('Runs - Platts'!$B$2:$B$97,'Runs - Platts'!$G$2:$G$97,$A6) -> 27432.994 | E6: 0.021563583 | F6: 0.27936637 | G6: 0.26104282 | H6: 0.43893722 | J6: -136.64667
A7: 43983 | B7: 0.2 | D7: =+SUMIFS('Runs - Platts'!$B$2:$B$97,'Runs - Platts'!$G$2:$G$97,$A7) -> 28511.269 | E7: 0.016322751 | F7: 0.28449171 | G7: 0.29136407 | H7: 0.36771716 | J7: -91.37
A8: 44013 | B8: 0 | D8: =+SUMIFS('Runs - Platts'!$B$2:$B$97,'Runs - Platts'!$G$2:$G$97,$A8) -> 28096.593 | E8: 0.015152397 | F8: 0.20615211 | G8: 0.3181847 | H8: 0.35150727 | J8: -172.2175
A9: 44044 | B9: 0 | D9: =+SUMIFS('Runs - Platts'!$B$2:$B$97,'Runs - Platts'!$G$2:$G$97,$A9) -> 27895.524 | E9: 0.024501445 | F9: 0.26041459 | G9: 0.3882675 | H9: 0.47325647 | J9: -190.13
A10: 44075 | B10: 0 | D10: =+SUMIFS('Runs - Platts'!$B$2:$B$97,'Runs - Platts'!$G$2:$G$97,$A10) -> 28385.187 | E10: 0.016348985 | F10: 0.26931474 | G10: 0.30124637 | H10: 0.39245086 | J10: -204.4575
A11: 44105 | B11: 0.2 | D11: =+SUMIFS('Runs - Platts'!$B$2:$B$97,'Runs - Platts'!$G$2:$G$97,$A11) -> 28376.806 | E11: 0.017642663 | F11: 0.20592437 | G11: 0.28127123 | H11: 0.3252166 | J11: -220.995
A12: 44136 | B12: 0.1 | D12: =+SUMIFS('Runs - Platts'!$B$2:$B$97,'Runs - Platts'!$G$2:$G$97,$A12) -> 29576.269 | E12: 0.01744372 | F12: 0.20372584 | G12: 0.25236787 | H12: 0.34175192 | J12: -198.085
A13: 44166 | B13: 0.3 | D13: =+SUMIFS('Runs - Platts'!$B$2:$B$97,'Runs - Platts'!$G$2:$G$97,$A13) -> 30338.462 | E13: 0.013060308 | F13: 0.27643137 | G13: 0.30257417 | H13: 0.27992749 | J13: -207.28667
A14: 44197 | B14: 0.05 | D14: =+SUMIFS('Runs - Platts'!$B$2:$B$97,'Runs - Platts'!$G$2:$G$97,$A14) -> 29820.63 | E14: 0.019259076 | F14: 0.26884985 | G14: 0.27723428 | H14: 0.20219216 | J14: -243.2
A15: 44228 | B15: -0.25 | D15: =+SUMIFS('Runs - Platts'!$B$2:$B$97,'Runs - Platts'!$G$2:$G$97,$A15) -> 29438.077 | E15: 0.012315158 | F15: 0.29477378 | G15: 0.32165316 | H15: 0.2196393 | I15: -0.1164038 | J15: -260.08
A16: 44256 | B16: -0.25 | D16: =+SUMIFS('Runs - Platts'!$B$2:$B$97,'Runs - Platts'!$G$2:$G$97,$A16) -> 29167.325 | E16: 0.022336794 | F16: 0.20315392 | G16: 0.3112165 | H16: 0.25546997 | I16: 0.42937685 | J16: -281.76875
A17: 44287 | B17: -0.45 | D17: =+SUMIFS('Runs - Platts'!$B$2:$B$97,'Runs - Platts'!$G$2:$G$97,$A17) -> 29398.073 | E17: 0.011244901 | F17: 0.28959473 | G17: 0.25044991 | H17: 0.36557138 | I17: 0.2974779 | J17: -306.51375
A18: 44317 | B18: -0.35 | D18: =+SUMIFS('Runs - Platts'!$B$2:$B$97,'Runs - Platts'!$G$2:$G$97,$A18) -> 28851.878 | E18: 0.025860734 | F18: 0.31983912 | G18: 0.33682494 | H18: 0.44159832 | I18: 0.86201146 | J18: -296.27
A19: 44348 | B19: -0.45 | D19: =+SUMIFS('Runs - Platts'!$B$2:$B$97,'Runs - Platts'!$G$2:$G$97,$A19) -> 29142.889 | E19: 0.022848004 | F19: 0.297828 | G19: 0.2726618 | H19: 0.51207226 | I19: 1.2406609 | J19: -318.225
A20: 44378 | B20: -0.55 | D20: =+SUMIFS('Runs - Platts'!$B$2:$B$97,'Runs - Platts'!$G$2:$G$97,$A20) -> 29111.442 | E20: 0.018735418 | F20: 0.37925117 | G20: 0.34715966 | H20: 0.47608816 | I20: 1.0240528 | J20: -324.85875
A21: 44409 | B21: -0.55 | D21: =+SUMIFS('Runs - Platts'!$B$2:$B$97,'Runs - Platts'!$G$2:$G$97,$A21) -> 29232.45 | E21: 0.023642857 | F21: 0.24227991 | G21: 0.31901779 | H21: 0.38869841 | I21: 1.2257308 | J21: -346.685
A22: 44440 | B22: -0.55 | D22: =+SUMIFS('Runs - Platts'!$B$2:$B$97,'Runs - Platts'!$G$2:$G$97,$A22) -> 28850.597 | E22: 0.011584526 | F22: 0.30534316 | G22: 0.24180969 | H22: 0.46147301 | I22: 1.8999876 | J22: -340.485
A23: 44470 | B23: -0.25 | D23: =+SUMIFS('Runs - Platts'!$B$2:$B$97,'Runs - Platts'!$G$2:$G$97,$A23) -> 29619.797 | E23: 0.021215234 | F23: 0.36073126 | G23: 0.21122287 | H23: 0.49196715 | I23: 2.4795872 | J23: -354.07667
A24: 44501 | B24: -0.25 | D24: =+SUMIFS('Runs - Platts'!$B$2:$B$97,'Runs - Platts'!$G$2:$G$97,$A24) -> 30410.702 | E24: 0.017175486 | F24: 0.35102469 | G24: 0.26992839 | H24: 0.45465735 | I24: 1.0752214 | J24: -389.785
A25: 44531 | B25: -0.35 | D25: =+SUMIFS('Runs - Platts'!$B$2:$B$97,'Runs - Platts'!$G$2:$G$97,$A25) -> 30310.826 | E25: 0.016855037 | F25: 0.33792835 | G25: 0.2231613 | H25: 0.45300957 | I25: 0.26345057 | J25: -371.68667
A26: 44562 | B26: -0.25 | D26: =+SUMIFS('Runs - Platts'!$B$2:$B$97,'Runs - Platts'!$G$2:$G$97,$A26) -> 30426.176 | E26: 0.018279761 | F26: 0.23095821 | G26: 0.18283932 | H26: 0.40400255 | I26: 1.6374441 | J26: -316.30667
... A31: 44713 | B31: -0.05 | D31: =+SUMIFS('Runs - Platts'!$B$2:$B$97,'Runs - Platts'!$G$2:$G$97,$A31) -> 29176.626 | E31: 0.016507794 | F31: 0.24283781 | G31: 0.16662188 | H31: 0.34536953 | I31: 9.032126 | J31: -579.02
A32: 44743 | B32: -0.35 | C32: 6.6533333 | D32: =+SUMIFS('Runs - Platts'!$B$2:$B$97,'Runs - Platts'!$G$2:$G$97,$A32) -> 29232.066 | E32: 0.012702636 | F32: 0.24384917 | G32: 0.20691066 | H32: 0.3696064 | I32: 3.8007057 | J32: -491.10667
A33: 44774 | B33: -2.15 | C33: 9.06 | D33: =+SUMIFS('Runs - Platts'!$B$2:$B$97,'Runs - Platts'!$G$2:$G$97,$A33) -> 29033.85 | E33: 0.012931147 | F33: 0.2330686 | G33: 0.12784188 | H33: 0.35676404 | I33: 5.2640534 | J33: -416.085
A34: 44805 | B34: -2.05 | C34: 5.655 | D34: =+SUMIFS('Runs - Platts'!$B$2:$B$97,'Runs - Platts'!$G$2:$G$97,$A34) -> 29723.418 | E34: 0.022633671 | F34: 0.28355486 | G34: 0.26273045 | H34: 0.38978071 | I34: 8.4170578 | J34: -374.2425
A35: 44835 | B35: -2.1 | C35: 4.385 | D35: =+SUMIFS('Runs - Platts'!$B$2:$B$97,'Runs - Platts'!$G$2:$G$97,$A35) -> 29408.102 | E35: 0.014188377 | F35: 0.2486159 | G35: 0.24953146 | H35: 0.39264714 | I35: 8.5101961 | J35: -321.72
A36: 44866 | B36: -1.85 | C36: 4.82 | D36: =+SUMIFS('Runs - Platts'!$B$2:$B$97,'Runs - Platts'!$G$2:$G$97,$A36) -> 29775.093 | E36: 0.014509144 | F36: 0.21067932 | G36: 0.25879097 | H36: 0.3571268 | I36: 3.7999047 | J36: -268.535
A37: 44896 | B37: -2.25 | C37: 3.615 | D37: =+SUMIFS('Runs - Platts'!$B$2:$B$97,'Runs - Platts'!$G$2:$G$97,$A37) -> 30678.928 | E37: 0.014978631 | F37: 0.23218204 | G37: 0.29314644 | H37: 0.36892695 | I37: 3.8911744 | J37: -295.495
A38: 44927 | B38: -1.15 | C38: 0.34 | D38: =+SUMIFS('Runs - Platts'!$B$2:$B$97,'Runs - Platts'!$G$2:$G$97,$A38) -> 30858.769 | E38: 0.016525379 | F38: 0.24229214 | G38: 0.25959839 | H38: 0.36109465 | I38: 3.7546197 | J38: -273.11
A39: 44958 | B39: -0.7 | C39: 1.01 | D39: =+SUMIFS('Runs - Platts'!$B$2:$B$97,'Runs - Platts'!$G$2:$G$97,$A39) -> 31659.698 | E39: 0.019944541 | F39: 0.38674589 | G39: 0.31869611 | H39: 0.47063275 | I39: 2.226475 | J39: -281.595
A40: 44986 | B40: -0.4 | C40: 0.83666667 | D40: =+SUMIFS('Runs - Platts'!$B$2:$B$97,'Runs - Platts'!$G$2:$G$97,$A40) -> 31151.079 | E40: 0.018909159 | F40: 0.19248465 | G40: 0.20063118 | H40: 0.38317646 | I40: 0.68460408 | J40: -289.18833
A41: 45017 | B41: 0 | C41: 1.25 | D41: =+SUMIFS('Runs - Platts'!$B$2:$B$97,'Runs - Platts'!$G$2:$G$97,$A41) -> 31016.261 | E41: 0.015735929 | F41: 0.23582649 | G41: 0.22137992 | H41: 0.43399978 | I41: 1.1456691 | J41: -353.64833
A42: 45047 | B42: 0 | C42: 1.015 | D42: =+SUMIFS('Runs - Platts'!$B$2:$B$97,'Runs - Platts'!$G$2:$G$97,$A42) -> 30997.63 | E42: 0.01973898 | F42: 0.33160267 | G42: 0.22653498 | H42: 0.40884801 | I42: 2.2691264 | J42: -372.265
A43: 45078 | B43: -0.55 | C43: 0.63 | D43: =+SUMIFS('Runs - Platts'!$B$2:$B$97,'Runs - Platts'!$G$2:$G$97,$A43) -> 30038.308 | E43: 0.015542186 | F43: 0.3194258 | G43: 0.1513194 | H43: 0.43737578 | I43: 2.9559084 | J43: -351.93833
... A72: 45962 | B72: -0.75 | C72: 0.10666667 | D72: =+SUMIFS('Runs - Platts'!$B$2:$B$97,'Runs - Platts'!$G$2:$G$97,$A72) -> 31102.5 | E72: 0.015115248 | F72: 0.26725038 | G72: 0.22146566 | H72: 0.41826243 | I72: 1.5565478 | J72: -323.69333
...

Sheet OSP Med-Light spread
A1: Description | B1: Arab Med Diff to (Oman+Dubai)/2 | C1: Arab Lt Diff to (Oman+Dubai)/2
A2: Currency/UOM | B2: USD/bbl | C2: USD/bbl
A3: Symbol Code | B3: AAIQX00 | C3: AAIQW00
A4: Bate | B4: Middle Price Index | C4: Middle Price Index | D4: Med-Light Spread
A5: 46082 | B5: -1.25 | C5: 0 | D5: =+B5-C5 -> -1.25
A6: 46054 | B6: -0.85 | C6: 0.3 | D6: =+B6-C6 -> -1.15
A7: 46023 | B7: -0.55 | C7: 0.6 | D7: =+B7-C7 -> -1.15
A8: 45992 | B8: 0.05 | C8: 1 | D8: =+B8-C8 -> -0.95
A9: 45962 | B9: 1.45 | C9: 2.2 | D9: =+B9-C9 -> -0.75
A10: 45931 | B10: 1.75 | C10: 2.2 | D10: =+B10-C10 -> -0.45
A11: 45901 | B11: 2.65 | C11: 3.2 | D11: =+B11-C11 -> -0.55
A12: 45870 | B12: 1.75 | C12: 2.2 | D12: =+B12-C12 -> -0.45
A13: 45839 | B13: 0.75 | C13: 1.2 | D13: =+B13-C13 -> -0.45
A14: 45809 | B14: 0.85 | C14: 1.4 | D14: =+B14-C14 -> -0.55
A15: 45778 | B15: 0.65 | C15: 1.2 | D15: =+B15-C15 -> -0.55
A16: 45748 | B16: 2.95 | C16: 3.5 | D16: =+B16-C16 -> -0.55
... A451: 32509 | B451: -0.7 | C451: 0 | D451: =+B451-C451 -> -0.7

Sheet Qatar Marine FOB
A1: Description | B1: Qatar Marine FOB Qatar vs Dubai Mo01
A2: Currency/UOM | B2: USD/bbl
A3: Symbol Code | B3: QAMDA00
A4: Bate | B4: Close | L4: Monthly | M4: Monthly (1-4) | O4: Yes/No
A5: 46055 | B5: -0.21 | D5: =+DAY(A5) -> 2 | E5: 1 | F5: =+MONTH(A5) -> 2 | G5: =+YEAR(A5) -> 2026 | I5: =+DATE(G5,F5,E5) -> 46054 | K5: 46054 | L5: =+AVERAGEIFS($B$5:$B$928,$I$5:$I$928,$K5) -> -0.21 | M5: =+AVERAGEIFS($B$5:$B$928,$I$5:$I$928,$K5,$O$5:$O$928,1) -> -0.21 | O5: =IF(AND(D5>=1, D5<=4), 1, 0) -> 1
A6: 46052 | B6: -0.95 | D6: =+DAY(A6) -> 30 | E6: 1 | F6: =+MONTH(A6) -> 1 | G6: =+YEAR(A6) -> 2026 | I6: =+DATE(G6,F6,E6) -> 46023 | K6: 46023 | L6: =+AVERAGEIFS($B$6:$B$928,$I$6:$I$928,$K6) -> -0.98333333 | M6: =+AVERAGEIFS($B$6:$B$928,$I$6:$I$928,$K6,$O$6:$O$928,1) -> -0.91 | O6: =IF(AND(D6>=1, D6<=4), 1, 0) -> 0
A7: 46051 | B7: -0.82 | D7: =+DAY(A7) -> 29 | E7: 1 | F7: =+MONTH(A7) -> 1 | G7: =+YEAR(A7) -> 2026 | I7: =+DATE(G7,F7,E7) -> 46023 | K7: 45992 | L7: =+AVERAGEIFS($B$6:$B$928,$I$6:$I$928,$K7) -> -0.16045455 | M7: =+AVERAGEIFS($B$6:$B$928,$I$6:$I$928,$K7,$O$6:$O$928,1) -> 3.469447e-18 | O7: =IF(AND(D7>=1, D7<=4), 1, 0) -> 0
A8: 46050 | B8: -0.84 | D8: =+DAY(A8) -> 28 | E8: 1 | F8: =+MONTH(A8) -> 1 | G8: =+YEAR(A8) -> 2026 | I8: =+DATE(G8,F8,E8) -> 46023 | K8: 45962 | L8: =+AVERAGEIFS($B$6:$B$928,$I$6:$I$928,$K8) -> 0.215 | M8: =+AVERAGEIFS($B$6:$B$928,$I$6:$I$928,$K8,$O$6:$O$928,1) -> 1.17 | O8: =IF(AND(D8>=1, D8<=4), 1, 0) -> 0
A9: 46049 | B9: -0.72 | D9: =+DAY(A9) -> 27 | E9: 1 | F9: =+MONTH(A9) -> 1 | G9: =+YEAR(A9) -> 2026 | I9: =+DATE(G9,F9,E9) -> 46023 | K9: 45931 | L9: =+AVERAGEIFS($B$6:$B$928,$I$6:$I$928,$K9) -> 0.62227273 | M9: =+AVERAGEIFS($B$6:$B$928,$I$6:$I$928,$K9,$O$6:$O$928,1) -> 0.10666667 | O9: =IF(AND(D9>=1, D9<=4), 1, 0) -> 0
A10: 46048 | B10: -0.84 | D10: =+DAY(A10) -> 26 | E10: 1 | F10: =+MONTH(A10) -> 1 | G10: =+YEAR(A10) -> 2026 | I10: =+DATE(G10,F10,E10) -> 46023 | K10: 45901 | L10: =+AVERAGEIFS($B$6:$B$928,$I$6:$I$928,$K10) -> 2.1836364 | M10: =+AVERAGEIFS($B$6:$B$928,$I$6:$I$928,$K10,$O$6:$O$928,1) -> 2.7475 | O10: =IF(AND(D10>=1, D10<=4), 1, 0) -> 0
A11: 46045 | B11: -1.06 | D11: =+DAY(A11) -> 23 | E11: 1 | F11: =+MONTH(A11) -> 1 | G11: =+YEAR(A11) -> 2026 | I11: =+DATE(G11,F11,E11) -> 46023 | K11: 45870 | L11: =+AVERAGEIFS($B$6:$B$928,$I$6:$I$928,$K11) -> 1.8119048 | M11: =+AVERAGEIFS($B$6:$B$928,$I$6:$I$928,$K11,$O$6:$O$928,1) -> 2.29 | O11: =IF(AND(D11>=1, D11<=4), 1, 0) -> 0
A12: 46044 | B12: -0.96 | D12: =+DAY(A12) -> 22 | E12: 1 | F12: =+MONTH(A12) -> 1 | G12: =+YEAR(A12) -> 2026 | I12: =+DATE(G12,F12,E12) -> 46023 | K12: 45839 | L12: =+AVERAGEIFS($B$6:$B$928,$I$6:$I$928,$K12) -> 2.5017391 | M12: =+AVERAGEIFS($B$6:$B$928,$I$6:$I$928,$K12,$O$6:$O$928,1) -> 2.865 | O12: =IF(AND(D12>=1, D12<=4), 1, 0) -> 0
A13: 46043 | B13: -0.93 | D13: =+DAY(A13) -> 21 | E13: 1 | F13: =+MONTH(A13) -> 1 | G13: =+YEAR(A13) -> 2026 | I13: =+DATE(G13,F13,E13) -> 46023 | K13: 45809 | L13: =+AVERAGEIFS($B$6:$B$928,$I$6:$I$928,$K13) -> 1.7428571 | M13: =+AVERAGEIFS($B$6:$B$928,$I$6:$I$928,$K13,$O$6:$O$928,1) -> 0.98666667 | O13: =IF(AND(D13>=1, D13<=4), 1, 0) -> 0
A14: 46042 | B14: -0.74 | D14: =+DAY(A14) -> 20 | E14: 1 | F14: =+MONTH(A14) -> 1 | G14: =+YEAR(A14) -> 2026 | I14: =+DATE(G14,F14,E14) -> 46023 | K14: 45778 | L14: =+AVERAGEIFS($B$6:$B$928,$I$6:$I$928,$K14) -> 0.919 | M14: =+AVERAGEIFS($B$6:$B$928,$I$6:$I$928,$K14,$O$6:$O$928,1) -> 0.28 | O14: =IF(AND(D14>=1, D14<=4), 1, 0) -> 0
A15: 46041 | B15: -0.75 | D15: =+DAY(A15) -> 19 | E15: 1 | F15: =+MONTH(A15) -> 1 | G15: =+YEAR(A15) -> 2026 | I15: =+DATE(G15,F15,E15) -> 46023 | K15: 45748 | L15: =+AVERAGEIFS($B$6:$B$928,$I$6:$I$928,$K15) -> 0.8352381 | M15: =+AVERAGEIFS($B$6:$B$928,$I$6:$I$928,$K15,$O$6:$O$928,1) -> 1.3675 | O15: =IF(AND(D15>=1, D15<=4), 1, 0) -> 0
A16: 46038 | B16: -0.67 | D16: =+DAY(A16) -> 16 | E16: 1 | F16: =+MONTH(A16) -> 1 | G16: =+YEAR(A16) -> 2026 | I16: =+DATE(G16,F16,E16) -> 46023 | K16: 45717 | L16: =+AVERAGEIFS($B$6:$B$928,$I$6:$I$928,$K16) -> 0.447 | M16: =+AVERAGEIFS($B$6:$B$928,$I$6:$I$928,$K16,$O$6:$O$928,1) -> -0.16 | O16: =IF(AND(D16>=1, D16<=4), 1, 0) -> 0
A17: 46037 | B17: -0.84 | D17: =+DAY(A17) -> 15 | E17: 1 | F17: =+MONTH(A17) -> 1 | G17: =+YEAR(A17) -> 2026 | I17: =+DATE(G17,F17,E17) -> 46023 | K17: 45689 | L17: =+AVERAGEIFS($B$6:$B$928,$I$6:$I$928,$K17) -> 2.399 | M17: =+AVERAGEIFS($B$6:$B$928,$I$6:$I$928,$K17,$O$6:$O$928,1) -> 2.93 | O17: =IF(AND(D17>=1, D17<=4), 1, 0) -> 0
... A450: 45408 | B450: 1.7 | D450: =+DAY(A450) -> 26 | E450: 1 | F450: =+MONTH(A450) -> 4 | G450: =+YEAR(A450) -> 2024 | I450: =+DATE(G450,F450,E450) -> 45383 | K450: 32509 | L450: =+AVERAGEIFS($B$6:$B$928,$I$6:$I$928,$K450) -> #DIV/0! | M450: =+AVERAGEIFS($B$6:$B$928,$I$6:$I$928,$K450,$O$6:$O$928,1) -> #DIV/0! | O450: =IF(AND(D450>=1, D450<=4), 1, 0) -> 0
A451: 45407 | B451: 1.84 | D451: =+DAY(A451) -> 25 | E451: 1 | F451: =+MONTH(A451) -> 4 | G451: =+YEAR(A451) -> 2024 | I451: =+DATE(G451,F451,E451) -> 45383 | O451: =IF(AND(D451>=1, D451<=4), 1, 0) -> 0
A452: 45406 | B452: 2.08 | D452: =+DAY(A452) -> 24 | E452: 1 | F452: =+MONTH(A452) -> 4 | G452: =+YEAR(A452) -> 2024 | I452: =+DATE(G452,F452,E452) -> 45383 | O452: =IF(AND(D452>=1, D452<=4), 1, 0) -> 0
A453: 45405 | B453: 1.79 | D453: =+DAY(A453) -> 23 | E453: 1 | F453: =+MONTH(A453) -> 4 | G453: =+YEAR(A453) -> 2024 | I453: =+DATE(G453,F453,E453) -> 45383 | O453: =IF(AND(D453>=1, D453<=4), 1, 0) -> 0
A454: 45404 | B454: 1.63 | D454: =+DAY(A454) -> 22 | E454: 1 | F454: =+MONTH(A454) -> 4 | G454: =+YEAR(A454) -> 2024 | I454: =+DATE(G454,F454,E454) -> 45383 | O454: =IF(AND(D454>=1, D454<=4), 1, 0) -> 0
A455: 45401 | B455: 1.69 | D455: =+DAY(A455) -> 19 | E455: 1 | F455: =+MONTH(A455) -> 4 | G455: =+YEAR(A455) -> 2024 | I455: =+DATE(G455,F455,E455) -> 45383 | O455: =IF(AND(D455>=1, D455<=4), 1, 0) -> 0
A456: 45400 | B456: 1.51 | D456: =+DAY(A456) -> 18 | E456: 1 | F456: =+MONTH(A456) -> 4 | G456: =+YEAR(A456) -> 2024 | I456: =+DATE(G456,F456,E456) -> 45383 | O456: =IF(AND(D456>=1, D456<=4), 1, 0) -> 0
A457: 45399 | B457: 1.35 | D457: =+DAY(A457) -> 17 | E457: 1 | F457: =+MONTH(A457) -> 4 | G457: =+YEAR(A457) -> 2024 | I457: =+DATE(G457,F457,E457) -> 45383 | O457: =IF(AND(D457>=1, D457<=4), 1, 0) -> 0
A458: 45398 | B458: 1.35 | D458: =+DAY(A458) -> 16 | E458: 1 | F458: =+MONTH(A458) -> 4 | G458: =+YEAR(A458) -> 2024 | I458: =+DATE(G458,F458,E458) -> 45383 | O458: =IF(AND(D458>=1, D458<=4), 1, 0) -> 0
A459: 45397 | B459: 1.38 | D459: =+DAY(A459) -> 15 | E459: 1 | F459: =+MONTH(A459) -> 4 | G459: =+YEAR(A459) -> 2024 | I459: =+DATE(G459,F459,E459) -> 45383 | O459: =IF(AND(D459>=1, D459<=4), 1, 0) -> 0
A460: 45394 | B460: 1.41 | D460: =+DAY(A460) -> 12 | E460: 1 | F460: =+MONTH(A460) -> 4 | G460: =+YEAR(A460) -> 2024 | I460: =+DATE(G460,F460,E460) -> 45383 | O460: =IF(AND(D460>=1, D460<=4), 1, 0) -> 0
A461: 45393 | B461: 1.62 | D461: =+DAY(A461) -> 11 | E461: 1 | F461: =+MONTH(A461) -> 4 | G461: =+YEAR(A461) -> 2024 | I461: =+DATE(G461,F461,E461) -> 45383 | O461: =IF(AND(D461>=1, D461<=4), 1, 0) -> 0
A462: 45391 | B462: 1.52 | D462: =+DAY(A462) -> 9 | E462: 1 | F462: =+MONTH(A462) -> 4 | G462: =+YEAR(A462) -> 2024 | I462: =+DATE(G462,F462,E462) -> 45383 | O462: =IF(AND(D462>=1, D462<=4), 1, 0) -> 0
... A928: 44713 | B928: 7.02 | D928: =+DAY(A928) -> 1 | E928: 1 | F928: =+MONTH(A928) -> 6 | G928: =+YEAR(A928) -> 2022 | I928: =+DATE(G928,F928,E928) -> 44713 | O928: =IF(AND(D928>=1, D928<=4), 1, 0) -> 1

Sheet Runs - Platts
B1: Asia-Pacific | D1: Year | E1: Month | F1: day | G1: Date
A2: 43831 | B2: 31286.883 | D2: =+YEAR(A2) -> 2020 | E2: =+MONTH(A2) -> 1 | F2: 1 | G2: =+DATE(D2,E2,F2) -> 43831
A3: 43862 | B3: 27448.856 | D3: =+YEAR(A3) -> 2020 | E3: =+MONTH(A3) -> 2 | F3: 1 | G3: =+DATE(D3,E3,F3) -> 43862
A4: 43891 | B4: 28237.405 | D4: =+YEAR(A4) -> 2020 | E4: =+MONTH(A4) -> 3 | F4: 1 | G4: =+DATE(D4,E4,F4) -> 43891
A5: 43922 | B5: 27243.656 | D5: =+YEAR(A5) -> 2020 | E5: =+MONTH(A5) -> 4 | F5: 1 | G5: =+DATE(D5,E5,F5) -> 43922
A6: 43952 | B6: 27432.994 | D6: =+YEAR(A6) -> 2020 | E6: =+MONTH(A6) -> 5 | F6: 1 | G6: =+DATE(D6,E6,F6) -> 43952
A7: 43983 | B7: 28511.269 | D7: =+YEAR(A7) -> 2020 | E7: =+MONTH(A7) -> 6 | F7: 1 | G7: =+DATE(D7,E7,F7) -> 43983
A8: 44013 | B8: 28096.593 | D8: =+YEAR(A8) -> 2020 | E8: =+MONTH(A8) -> 7 | F8: 1 | G8: =+DATE(D8,E8,F8) -> 44013
A9: 44044 | B9: 27895.524 | D9: =+YEAR(A9) -> 2020 | E9: =+MONTH(A9) -> 8 | F9: 1 | G9: =+DATE(D9,E9,F9) -> 44044
A10: 44075 | B10: 28385.187 | D10: =+YEAR(A10) -> 2020 | E10: =+MONTH(A10) -> 9 | F10: 1 | G10: =+DATE(D10,E10,F10) -> 44075
A11: 44105 | B11: 28376.806 | D11: =+YEAR(A11) -> 2020 | E11: =+MONTH(A11) -> 10 | F11: 1 | G11: =+DATE(D11,E11,F11) -> 44105
A12: 44136 | B12: 29576.269 | D12: =+YEAR(A12) -> 2020 | E12: =+MONTH(A12) -> 11 | F12: 1 | G12: =+DATE(D12,E12,F12) -> 44136
A13: 44166 | B13: 30338.462 | D13: =+YEAR(A13) -> 2020 | E13: =+MONTH(A13) -> 12 | F13: 1 | G13: =+DATE(D13,E13,F13) -> 44166
... A97: 46722 | B97: 32520.061 | D97: =+YEAR(A97) -> 2027 | E97: =+MONTH(A97) -> 12 | F97: 1 | G97: =+DATE(D97,E97,F97) -> 46722

Sheet Exports MoE
A1: Date | B1: ASL | C1: AXL | D1: AL | E1: AM | F1: AH | H1: ASL/AL | I1: AXL/AL | J1: AM/AL | K1: AH/AL
A2: 43831 | B2: 2673751 | C2: 25695979 | D2: 151646935 | E2: 46867899 | F2: 51205450 | H2: =+B2/D2 -> 0.017631421 | I2: =+C2/D2 -> 0.16944608 | J2: =+E2/D2 -> 0.30905932 | K2: =+F2/D2 -> 0.33766228
A3: 43862 | B3: 2590753 | C3: 34567509 | D3: 130200749 | E3: 39020363 | F3: 40477184 | H3: =+B3/D3 -> 0.019898142 | I3: =+C3/D3 -> 0.26549393 | J3: =+E3/D3 -> 0.29969384 | K3: =+F3/D3 -> 0.31088288
A4: 43891 | B4: 2681421 | C4: 34739072 | D4: 124349513 | E4: 32460548 | F4: 54581630 | H4: =+B4/D4 -> 0.021563583 | I4: =+C4/D4 -> 0.27936637 | J4: =+E4/D4 -> 0.26104282 | K4: =+F4/D4 -> 0.43893722
A5: 43922 | B5: 2755524 | C5: 48026447 | D5: 168814927 | E5: 49186604 | F5: 62076145 | H5: =+B5/D5 -> 0.016322751 | I5: =+C5/D5 -> 0.28449171 | J5: =+E5/D5 -> 0.29136407 | K5: =+F5/D5 -> 0.36771716
A6: 43952 | B6: 2053865 | C6: 27943341 | D6: 135547198 | E6: 43129045 | F6: 47645826 | H6: =+B6/D6 -> 0.015152397 | I6: =+C6/D6 -> 0.20615211 | J6: =+E6/D6 -> 0.3181847 | K6: =+F6/D6 -> 0.35150727
A7: 43983 | B7: 2416828 | C7: 25687353 | D7: 98640223 | E7: 38298793 | F7: 46682124 | H7: =+B7/D7 -> 0.024501445 | I7: =+C7/D7 -> 0.26041459 | J7: =+E7/D7 -> 0.3882675 | K7: =+F7/D7 -> 0.47325647
A8: 44013 | B8: 1858140 | C8: 30608903 | D8: 113654764 | E8: 34238085 | F8: 44603910 | H8: =+B8/D8 -> 0.016348985 | I8: =+C8/D8 -> 0.26931474 | J8: =+E8/D8 -> 0.30124637 | K8: =+F8/D8 -> 0.39245086
A9: 44044 | B9: 2321208 | C9: 27093036 | D9: 131567893 | E9: 37006263 | F9: 42788063 | H9: =+B9/D9 -> 0.017642663 | I9: =+C9/D9 -> 0.20592437 | J9: =+E9/D9 -> 0.28127123 | K9: =+F9/D9 -> 0.3252166
A10: 44075 | B10: 2237011 | C10: 26126133 | D10: 128241628 | E10: 32364067 | F10: 43826822 | H10: =+B10/D10 -> 0.01744372 | I10: =+C10/D10 -> 0.20372584 | J10: =+E10/D10 -> 0.25236787 | K10: =+F10/D10 -> 0.34175192
A11: 44105 | B11: 1721586 | C11: 36438680 | D11: 131818181 | E11: 39884777 | F11: 36899533 | H11: =+B11/D11 -> 0.013060308 | I11: =+C11/D11 -> 0.27643137 | J11: =+E11/D11 -> 0.30257417 | K11: =+F11/D11 -> 0.27992749
A12: 44136 | B12: 2643137 | C12: 36897253 | D12: 137241113 | E12: 38047941 | F12: 27749077 | H12: =+B12/D12 -> 0.019259076 | I12: =+C12/D12 -> 0.26884985 | J12: =+E12/D12 -> 0.27723428 | K12: =+F12/D12 -> 0.20219216
A13: 44166 | B13: 1700452 | C13: 40701765 | D13: 138077971 | E13: 44413216 | F13: 30327349 | H13: =+B13/D13 -> 0.012315158 | I13: =+C13/D13 -> 0.29477378 | J13: =+E13/D13 -> 0.32165316 | K13: =+F13/D13 -> 0.2196393
... A70: 45901 | B70: 1942791 | C70: 34350190 | D70: 128531866 | E70: 28465394 | F70: 53760051 | H70: =+B70/D70 -> 0.015115248 | I70: =+C70/D70 -> 0.26725038 | J70: =+E70/D70 -> 0.22146566 | K70: =+F70/D70 -> 0.41826243
A71: 45931 | C71: 37853290 | D71: 1.2290797e+08 | E71: 29193007 | F71: 16603335 | H71: 0 | I71: 0.3088195 | J71: 0.24209043 | K71: 0.1401318 | M71: This is updated data from Vortexa as we haven't received the ministry update yet.
A72: 45962 | C72: 45458954 | D72: 1.0140798e+08 | E72: 25102712 | F72: 24844768 | H72: 0 | I72: 0.44216178 | J72: 0.26517282 | K72: 0.24809167
A73: 45992 | C73: 37412992 | D73: 1.240905e+08 | E73: 29642505 | F73: 9635496.8 | H73: 0 | I73: 0.42871391 | J73: 0.31009302 | K73: 0.14258218
A74: 46023 | C74: 15984990 | D74: 1.1617858e+08 | E74: 19976124 | F74: 2043400.6 | H74: 0 | I74: 0.24465361 | J74: 0.18339446 | K74: 0.049879717

Sheet Dubai-alight asia mgn
A1: margins
B2: Arab Light | C2: Dubai | D2: Arab XLight | E2: Arab Heavy
B3: VISB/FCC/HCU | C3: VISB/FCC/HCU | D3: TOPPING | E3: FCC/HCU/Coking | H3: Day | I3: Month | J3: Year | K3: Date | L3: Yes | O3: Arab Light | P3: Dubai | Q3: Dubai-ALT | R3: Arab XLight | S3: Xlt-ALT | T3: Arab Heavy | U3: Hvy-ALT
A4: 46055 | B4: 5.4804618 | C4: 5.2907166 | D4: 2.839272 | E4: 6.7120809 | G4: =+DAY(A4) -> 2 | H4: 1 | I4: =+MONTH(A4) -> 2 | J4: =+YEAR(A4) -> 2026 | K4: =+DATE(J4,I4,H4) -> 46054 | L4: =IF(AND(G4>=1, G4<=4), 1, 0) -> 1 | N4: 43831 | O4: =+IFERROR(AVERAGEIFS($B$4:$B$1231,$K$4:$K$1231,$N4,$L$4:$L$1231,1),"") | P4: =+IFERROR(AVERAGEIFS($C$4:$C$1231,$K$4:$K$1231,$N4,$L$4:$L$1231,1),"") | R4: =+IFERROR(AVERAGEIFS($D$4:$D$1231,$K$4:$K$1231,$N4,$L$4:$L$1231,1),"")
A5: 46052 | B5: 6.2758965 | C5: 6.3323171 | D5: 3.6995996 | E5: 7.394481 | G5: =+DAY(A5) -> 30 | H5: 1 | I5: =+MONTH(A5) -> 1 | J5: =+YEAR(A5) -> 2026 | K5: =+DATE(J5,I5,H5) -> 46023 | L5: =IF(AND(G5>=1, G5<=4), 1, 0) -> 0 | N5: 43862 | O5: =+IFERROR(AVERAGEIFS($B$4:$B$1231,$K$4:$K$1231,$N5,$L$4:$L$1231,1),"") | P5: =+IFERROR(AVERAGEIFS($C$4:$C$1231,$K$4:$K$1231,$N5,$L$4:$L$1231,1),"") | R5: =+IFERROR(AVERAGEIFS($D$4:$D$1231,$K$4:$K$1231,$N5,$L$4:$L$1231,1),"")
A6: 46051 | B6: 6.6217669 | C6: 6.6843198 | D6: 3.9957261 | E6: 7.7158542 | G6: =+DAY(A6) -> 29 | H6: 1 | I6: =+MONTH(A6) -> 1 | J6: =+YEAR(A6) -> 2026 | K6: =+DATE(J6,I6,H6) -> 46023 | L6: =IF(AND(G6>=1, G6<=4), 1, 0) -> 0 | N6: 43891 | O6: =+IFERROR(AVERAGEIFS($B$4:$B$1231,$K$4:$K$1231,$N6,$L$4:$L$1231,1),"") | P6: =+IFERROR(AVERAGEIFS($C$4:$C$1231,$K$4:$K$1231,$N6,$L$4:$L$1231,1),"") | R6: =+IFERROR(AVERAGEIFS($D$4:$D$1231,$K$4:$K$1231,$N6,$L$4:$L$1231,1),"")
A7: 46050 | B7: 6.6482339 | C7: 6.6805637 | D7: 3.8473648 | E7: 7.916479 | G7: =+DAY(A7) -> 28 | H7: 1 | I7: =+MONTH(A7) -> 1 | J7: =+YEAR(A7) -> 2026 | K7: =+DATE(J7,I7,H7) -> 46023 | L7: =IF(AND(G7>=1, G7<=4), 1, 0) -> 0 | N7: 43922 | O7: =+IFERROR(AVERAGEIFS($B$4:$B$1231,$K$4:$K$1231,$N7,$L$4:$L$1231,1),"") | P7: =+IFERROR(AVERAGEIFS($C$4:$C$1231,$K$4:$K$1231,$N7,$L$4:$L$1231,1),"") | R7: =+IFERROR(AVERAGEIFS($D$4:$D$1231,$K$4:$K$1231,$N7,$L$4:$L$1231,1),"")
A8: 46049 | B8: 6.1004461 | C8: 6.1574458 | D8: 3.2449838 | E8: 7.5247756 | G8: =+DAY(A8) -> 27 | H8: 1 | I8: =+MONTH(A8) -> 1 | J8: =+YEAR(A8) -> 2026 | K8: =+DATE(J8,I8,H8) -> 46023 | L8: =IF(AND(G8>=1, G8<=4), 1, 0) -> 0 | N8: 43952 | O8: =+IFERROR(AVERAGEIFS($B$4:$B$1231,$K$4:$K$1231,$N8,$L$4:$L$1231,1),"") | P8: =+IFERROR(AVERAGEIFS($C$4:$C$1231,$K$4:$K$1231,$N8,$L$4:$L$1231,1),"") | R8: =+IFERROR(AVERAGEIFS($D$4:$D$1231,$K$4:$K$1231,$N8,$L$4:$L$1231,1),"")
A9: 46048 | B9: 6.8008196 | C9: 6.9501608 | D9: 4.1235084 | E9: 8.0394748 | G9: =+DAY(A9) -> 26 | H9: 1 | I9: =+MONTH(A9) -> 1 | J9: =+YEAR(A9) -> 2026 | K9: =+DATE(J9,I9,H9) -> 46023 | L9: =IF(AND(G9>=1, G9<=4), 1, 0) -> 0 | N9: 43983 | O9: =+IFERROR(AVERAGEIFS($B$4:$B$1231,$K$4:$K$1231,$N9,$L$4:$L$1231,1),"") | P9: =+IFERROR(AVERAGEIFS($C$4:$C$1231,$K$4:$K$1231,$N9,$L$4:$L$1231,1),"") | R9: =+IFERROR(AVERAGEIFS($D$4:$D$1231,$K$4:$K$1231,$N9,$L$4:$L$1231,1),"")
A10: 46045 | B10: 6.3164428 | C10: 6.5600391 | D10: 3.3245011 | E10: 7.7542838 | G10: =+DAY(A10) -> 23 | H10: 1 | I10: =+MONTH(A10) -> 1 | J10: =+YEAR(A10) -> 2026 | K10: =+DATE(J10,I10,H10) -> 46023 | L10: =IF(AND(G10>=1, G10<=4), 1, 0) -> 0 | N10: 44013 | O10: =+IFERROR(AVERAGEIFS($B$4:$B$1231,$K$4:$K$1231,$N10,$L$4:$L$1231,1),"") | P10: =+IFERROR(AVERAGEIFS($C$4:$C$1231,$K$4:$K$1231,$N10,$L$4:$L$1231,1),"") | R10: =+IFERROR(AVERAGEIFS($D$4:$D$1231,$K$4:$K$1231,$N10,$L$4:$L$1231,1),"")
A11: 46044 | B11: 5.9548235 | C11: 6.0984725 | D11: 2.4748327 | E11: 7.6230255 | G11: =+DAY(A11) -> 22 | H11: 1 | I11: =+MONTH(A11) -> 1 | J11: =+YEAR(A11) -> 2026 | K11: =+DATE(J11,I11,H11) -> 46023 | L11: =IF(AND(G11>=1, G11<=4), 1, 0) -> 0 | N11: 44044 | O11: =+IFERROR(AVERAGEIFS($B$4:$B$1231,$K$4:$K$1231,$N11,$L$4:$L$1231,1),"") | P11: =+IFERROR(AVERAGEIFS($C$4:$C$1231,$K$4:$K$1231,$N11,$L$4:$L$1231,1),"") | R11: =+IFERROR(AVERAGEIFS($D$4:$D$1231,$K$4:$K$1231,$N11,$L$4:$L$1231,1),"")
A12: 46043 | B12: 5.756502 | C12: 5.9235211 | D12: 1.972291 | E12: 7.5349428 | G12: =+DAY(A12) -> 21 | H12: 1 | I12: =+MONTH(A12) -> 1 | J12: =+YEAR(A12) -> 2026 | K12: =+DATE(J12,I12,H12) -> 46023 | L12: =IF(AND(G12>=1, G12<=4), 1, 0) -> 0 | N12: 44075 | O12: =+IFERROR(AVERAGEIFS($B$4:$B$1231,$K$4:$K$1231,$N12,$L$4:$L$1231,1),"") | P12: =+IFERROR(AVERAGEIFS($C$4:$C$1231,$K$4:$K$1231,$N12,$L$4:$L$1231,1),"") | R12: =+IFERROR(AVERAGEIFS($D$4:$D$1231,$K$4:$K$1231,$N12,$L$4:$L$1231,1),"")
A13: 46042 | B13: 4.975612 | C13: 5.30251 | D13: 1.1622978 | E13: 6.7953364 | G13: =+DAY(A13) -> 20 | H13: 1 | I13: =+MONTH(A13) -> 1 | J13: =+YEAR(A13) -> 2026 | K13: =+DATE(J13,I13,H13) -> 46023 | L13: =IF(AND(G13>=1, G13<=4), 1, 0) -> 0 | N13: 44105 | O13: =+IFERROR(AVERAGEIFS($B$4:$B$1231,$K$4:$K$1231,$N13,$L$4:$L$1231,1),"") | P13: =+IFERROR(AVERAGEIFS($C$4:$C$1231,$K$4:$K$1231,$N13,$L$4:$L$1231,1),"") | R13: =+IFERROR(AVERAGEIFS($D$4:$D$1231,$K$4:$K$1231,$N13,$L$4:$L$1231,1),"")
A14: 46041 | B14: 4.6397095 | C14: 4.9761243 | D14: 0.97736086 | E14: 6.3716959 | G14: =+DAY(A14) -> 19 | H14: 1 | I14: =+MONTH(A14) -> 1 | J14: =+YEAR(A14) -> 2026 | K14: =+DATE(J14,I14,H14) -> 46023 | L14: =IF(AND(G14>=1, G14<=4), 1, 0) -> 0 | N14: 44136 | O14: =+IFERROR(AVERAGEIFS($B$4:$B$1231,$K$4:$K$1231,$N14,$L$4:$L$1231,1),"") | P14: =+IFERROR(AVERAGEIFS($C$4:$C$1231,$K$4:$K$1231,$N14,$L$4:$L$1231,1),"") | R14: =+IFERROR(AVERAGEIFS($D$4:$D$1231,$K$4:$K$1231,$N14,$L$4:$L$1231,1),"")
A15: 46038 | B15: 4.2820604 | C15: 4.6116995 | D15: 0.5883199 | E15: 6.0354383 | G15: =+DAY(A15) -> 16 | H15: 1 | I15: =+MONTH(A15) -> 1 | J15: =+YEAR(A15) -> 2026 | K15: =+DATE(J15,I15,H15) -> 46023 | L15: =IF(AND(G15>=1, G15<=4), 1, 0) -> 0 | N15: 44166 | O15: =+IFERROR(AVERAGEIFS($B$4:$B$1231,$K$4:$K$1231,$N15,$L$4:$L$1231,1),"") | P15: =+IFERROR(AVERAGEIFS($C$4:$C$1231,$K$4:$K$1231,$N15,$L$4:$L$1231,1),"") | R15: =+IFERROR(AVERAGEIFS($D$4:$D$1231,$K$4:$K$1231,$N15,$L$4:$L$1231,1),"")
A16: 46037 | B16: 4.5567619 | C16: 4.8903228 | D16: 0.66008919 | E16: 6.3735861 | G16: =+DAY(A16) -> 15 | H16: 1 | I16: =+MONTH(A16) -> 1 | J16: =+YEAR(A16) -> 2026 | K16: =+DATE(J16,I16,H16) -> 46023 | L16: =IF(AND(G16>=1, G16<=4), 1, 0) -> 0 | N16: 44197 | O16: =+IFERROR(AVERAGEIFS($B$4:$B$1231,$K$4:$K$1231,$N16,$L$4:$L$1231,1),"") | P16: =+IFERROR(AVERAGEIFS($C$4:$C$1231,$K$4:$K$1231,$N16,$L$4:$L$1231,1),"") | R16: =+IFERROR(AVERAGEIFS($D$4:$D$1231,$K$4:$K$1231,$N16,$L$4:$L$1231,1),"")
A17: 46036 | B17: 5.5117711 | C17: 5.7587649 | D17: 1.5139354 | E17: 7.3587022 | G17: =+DAY(A17) -> 14 | H17: 1 | I17: =+MONTH(A17) -> 1 | J17: =+YEAR(A17) -> 2026 | K17: =+DATE(J17,I17,H17) -> 46023 | L17: =IF(AND(G17>=1, G17<=4), 1, 0) -> 0 | N17: 44228 | O17: =+IFERROR(AVERAGEIFS($B$4:$B$1231,$K$4:$K$1231,$N17,$L$4:$L$1231,1),"") -> -0.51429294 | P17: =+IFERROR(AVERAGEIFS($C$4:$C$1231,$K$4:$K$1231,$N17,$L$4:$L$1231,1),"") -> -0.095166402 | Q17: =+P17-O17 -> 0.41912653 | R17: =+IFERROR(AVERAGEIFS($D$4:$D$1231,$K$4:$K$1231,$N17,$L$4:$L$1231,1),"") -> -1.3685237 | S17: =+R17-O17 -> -0.85423071 | T17: =+IFERROR(AVERAGEIFS($E$4:$E$1231,$K$4:$K$1231,$N17,$L$4:$L$1231,1),"") -> -1.0594986 | U17: =+T17-O17 -> -0.54520567
A18: 46035 | B18: 5.5838514 | C18: 5.7490076 | D18: 1.1648147 | E18: 7.6331858 | G18: =+DAY(A18) -> 13 | H18: 1 | I18: =+MONTH(A18) -> 1 | J18: =+YEAR(A18) -> 2026 | K18: =+DATE(J18,I18,H18) -> 46023 | L18: =IF(AND(G18>=1, G18<=4), 1, 0) -> 0 | N18: 44256 | O18: =+IFERROR(AVERAGEIFS($B$4:$B$1231,$K$4:$K$1231,$N18,$L$4:$L$1231,1),"") -> -0.10544695 | P18: =+IFERROR(AVERAGEIFS($C$4:$C$1231,$K$4:$K$1231,$N18,$L$4:$L$1231,1),"") -> 0.19203096 | Q18: =+P18-O18 -> 0.2974779 | R18: =+IFERROR(AVERAGEIFS($D$4:$D$1231,$K$4:$K$1231,$N18,$L$4:$L$1231,1),"") -> -1.4524107 | S18: =+R18-O18 -> -1.3469638 | T18: =+IFERROR(AVERAGEIFS($E$4:$E$1231,$K$4:$K$1231,$N18,$L$4:$L$1231,1),"") -> -0.87562051 | U18: =+T18-O18 -> -0.77017356
A19: 46034 | B19: 5.1869985 | C19: 5.2590211 | D19: 0.5813038 | E19: 7.2978013 | G19: =+DAY(A19) -> 12 | H19: 1 | I19: =+MONTH(A19) -> 1 | J19: =+YEAR(A19) -> 2026 | K19: =+DATE(J19,I19,H19) -> 46023 | L19: =IF(AND(G19>=1, G19<=4), 1, 0) -> 0 | N19: 44287 | O19: =+IFERROR(AVERAGEIFS($B$4:$B$1231,$K$4:$K$1231,$N19,$L$4:$L$1231,1),"") -> -1.9136763 | P19: =+IFERROR(AVERAGEIFS($C$4:$C$1231,$K$4:$K$1231,$N19,$L$4:$L$1231,1),"") -> -1.0516648 | Q19: =+P19-O19 -> 0.86201146 | R19: =+IFERROR(AVERAGEIFS($D$4:$D$1231,$K$4:$K$1231,$N19,$L$4:$L$1231,1),"") -> -3.7144378 | S19: =+R19-O19 -> -1.8007615 | T19: =+IFERROR(AVERAGEIFS($E$4:$E$1231,$K$4:$K$1231,$N19,$L$4:$L$1231,1),"") -> -2.2773072 | U19: =+T19-O19 -> -0.36363092
A20: 46031 | B20: 5.6206144 | C20: 5.7786825 | D20: 1.0728103 | E20: 7.645139 | G20: =+DAY(A20) -> 9 | H20: 1 | I20: =+MONTH(A20) -> 1 | J20: =+YEAR(A20) -> 2026 | K20: =+DATE(J20,I20,H20) -> 46023 | L20: =IF(AND(G20>=1, G20<=4), 1, 0) -> 0 | N20: 44317 | O20: =+IFERROR(AVERAGEIFS($B$4:$B$1231,$K$4:$K$1231,$N20,$L$4:$L$1231,1),"") -> -1.1767256 | P20: =+IFERROR(AVERAGEIFS($C$4:$C$1231,$K$4:$K$1231,$N20,$L$4:$L$1231,1),"") -> 0.063935355 | Q20: =+P20-O20 -> 1.2406609 | R20: =+IFERROR(AVERAGEIFS($D$4:$D$1231,$K$4:$K$1231,$N20,$L$4:$L$1231,1),"") -> -3.2031405 | S20: =+R20-O20 -> -2.026415 | T20: =+IFERROR(AVERAGEIFS($E$4:$E$1231,$K$4:$K$1231,$N20,$L$4:$L$1231,1),"") -> -1.8918484 | U20: =+T20-O20 -> -0.71512285
A21: 46030 | B21: 6.6071922 | C21: 6.7858071 | D21: 2.3132895 | E21: 8.6294328 | G21: =+DAY(A21) -> 8 | H21: 1 | I21: =+MONTH(A21) -> 1 | J21: =+YEAR(A21) -> 2026 | K21: =+DATE(J21,I21,H21) -> 46023 | L21: =IF(AND(G21>=1, G21<=4), 1, 0) -> 0 | N21: 44348 | O21: =+IFERROR(AVERAGEIFS($B$4:$B$1231,$K$4:$K$1231,$N21,$L$4:$L$1231,1),"") -> -2.1745602 | P21: =+IFERROR(AVERAGEIFS($C$4:$C$1231,$K$4:$K$1231,$N21,$L$4:$L$1231,1),"") -> -1.1505074 | Q21: =+P21-O21 -> 1.0240528 | R21: =+IFERROR(AVERAGEIFS($D$4:$D$1231,$K$4:$K$1231,$N21,$L$4:$L$1231,1),"") -> -4.1611077 | S21: =+R21-O21 -> -1.9865475 | T21: =+IFERROR(AVERAGEIFS($E$4:$E$1231,$K$4:$K$1231,$N21,$L$4:$L$1231,1),"") -> -2.4674598 | U21: =+T21-O21 -> -0.29289965
A22: 46029 | B22: 6.8985904 | C22: 7.2100327 | D22: 2.7796363 | E22: 8.807388 | G22: =+DAY(A22) -> 7 | H22: 1 | I22: =+MONTH(A22) -> 1 | J22: =+YEAR(A22) -> 2026 | K22: =+DATE(J22,I22,H22) -> 46023 | L22: =IF(AND(G22>=1, G22<=4), 1, 0) -> 0 | N22: 44378 | O22: =+IFERROR(AVERAGEIFS($B$4:$B$1231,$K$4:$K$1231,$N22,$L$4:$L$1231,1),"") -> -1.7992025 | P22: =+IFERROR(AVERAGEIFS($C$4:$C$1231,$K$4:$K$1231,$N22,$L$4:$L$1231,1),"") -> -0.57347167 | Q22: =+P22-O22 -> 1.2257308 | R22: =+IFERROR(AVERAGEIFS($D$4:$D$1231,$K$4:$K$1231,$N22,$L$4:$L$1231,1),"") -> -4.5167042 | S22: =+R22-O22 -> -2.7175017 | T22: =+IFERROR(AVERAGEIFS($E$4:$E$1231,$K$4:$K$1231,$N22,$L$4:$L$1231,1),"") -> -1.7071166 | U22: =+T22-O22 -> 0.092085889
A23: 46028 | B23: 7.1433974 | C23: 7.3863884 | D23: 2.6384081 | E23: 9.1624409 | G23: =+DAY(A23) -> 6 | H23: 1 | I23: =+MONTH(A23) -> 1 | J23: =+YEAR(A23) -> 2026 | K23: =+DATE(J23,I23,H23) -> 46023 | L23: =IF(AND(G23>=1, G23<=4), 1, 0) -> 0 | N23: 44409 | O23: =+IFERROR(AVERAGEIFS($B$4:$B$1231,$K$4:$K$1231,$N23,$L$4:$L$1231,1),"") -> -1.5566176 | P23: =+IFERROR(AVERAGEIFS($C$4:$C$1231,$K$4:$K$1231,$N23,$L$4:$L$1231,1),"") -> 0.34337003 | Q23: =+P23-O23 -> 1.8999876 | R23: =+IFERROR(AVERAGEIFS($D$4:$D$1231,$K$4:$K$1231,$N23,$L$4:$L$1231,1),"") -> -4.3359039 | S23: =+R23-O23 -> -2.7792864 | T23: =+IFERROR(AVERAGEIFS($E$4:$E$1231,$K$4:$K$1231,$N23,$L$4:$L$1231,1),"") -> -1.2521606 | U23: =+T23-O23 -> 0.30445693
A24: 46027 | B24: 7.0978379 | C24: 7.2512675 | D24: 2.4651645 | E24: 9.1716473 | G24: =+DAY(A24) -> 5 | H24: 1 | I24: =+MONTH(A24) -> 1 | J24: =+YEAR(A24) -> 2026 | K24: =+DATE(J24,I24,H24) -> 46023 | L24: =IF(AND(G24>=1, G24<=4), 1, 0) -> 0 | N24: 44440 | O24: =+IFERROR(AVERAGEIFS($B$4:$B$1231,$K$4:$K$1231,$N24,$L$4:$L$1231,1),"") -> -1.3155908 | P24: =+IFERROR(AVERAGEIFS($C$4:$C$1231,$K$4:$K$1231,$N24,$L$4:$L$1231,1),"") -> 1.1639964 | Q24: =+P24-O24 -> 2.4795872 | R24: =+IFERROR(AVERAGEIFS($D$4:$D$1231,$K$4:$K$1231,$N24,$L$4:$L$1231,1),"") -> -3.4483562 | S24: =+R24-O24 -> -2.1327654 | T24: =+IFERROR(AVERAGEIFS($E$4:$E$1231,$K$4:$K$1231,$N24,$L$4:$L$1231,1),"") -> -1.0604091 | U24: =+T24-O24 -> 0.25518171
A25: 46024 | B25: 5.964624 | C25: 6.1902632 | D25: 1.3270136 | E25: 8.0278678 | G25: =+DAY(A25) -> 2 | H25: 1 | I25: =+MONTH(A25) -> 1 | J25: =+YEAR(A25) -> 2026 | K25: =+DATE(J25,I25,H25) -> 46023 | L25: =IF(AND(G25>=1, G25<=4), 1, 0) -> 1 | N25: 44470 | O25: =+IFERROR(AVERAGEIFS($B$4:$B$1231,$K$4:$K$1231,$N25,$L$4:$L$1231,1),"") -> 2.5068238 | P25: =+IFERROR(AVERAGEIFS($C$4:$C$1231,$K$4:$K$1231,$N25,$L$4:$L$1231,1),"") -> 3.5820453 | Q25: =+P25-O25 -> 1.0752214 | R25: =+IFERROR(AVERAGEIFS($D$4:$D$1231,$K$4:$K$1231,$N25,$L$4:$L$1231,1),"") -> -0.15121254 | S25: =+R25-O25 -> -2.6580364 | T25: =+IFERROR(AVERAGEIFS($E$4:$E$1231,$K$4:$K$1231,$N25,$L$4:$L$1231,1),"") -> 2.6795269 | U25: =+T25-O25 -> 0.17270309
A26: 46022 | B26: 5.1084156 | C26: 5.5879032 | D26: 0.56977373 | E26: 6.9489136 | G26: =+DAY(A26) -> 31 | H26: 1 | I26: =+MONTH(A26) -> 12 | J26: =+YEAR(A26) -> 2025 | K26: =+DATE(J26,I26,H26) -> 45992 | L26: =IF(AND(G26>=1, G26<=4), 1, 0) -> 0 | N26: 44501 | O26: =+IFERROR(AVERAGEIFS($B$4:$B$1231,$K$4:$K$1231,$N26,$L$4:$L$1231,1),"") -> 3.8262787 | P26: =+IFERROR(AVERAGEIFS($C$4:$C$1231,$K$4:$K$1231,$N26,$L$4:$L$1231,1),"") -> 4.0897293 | Q26: =+P26-O26 -> 0.26345057 | R26: =+IFERROR(AVERAGEIFS($D$4:$D$1231,$K$4:$K$1231,$N26,$L$4:$L$1231,1),"") -> -1.7386859 | S26: =+R26-O26 -> -5.5649646 | T26: =+IFERROR(AVERAGEIFS($E$4:$E$1231,$K$4:$K$1231,$N26,$L$4:$L$1231,1),"") -> 4.9435373 | U26: =+T26-O26 -> 1.1172586
A27: 46021 | B27: 4.5582422 | C27: 5.0476217 | D27: 0.0079634144 | E27: 6.384292 | G27: =+DAY(A27) -> 30 | H27: 1 | I27: =+MONTH(A27) -> 12 | J27: =+YEAR(A27) -> 2025 | K27: =+DATE(J27,I27,H27) -> 45992 | L27: =IF(AND(G27>=1, G27<=4), 1, 0) -> 0 | N27: 44531 | O27: =+IFERROR(AVERAGEIFS($B$4:$B$1231,$K$4:$K$1231,$N27,$L$4:$L$1231,1),"") -> 0.061532168 | P27: =+IFERROR(AVERAGEIFS($C$4:$C$1231,$K$4:$K$1231,$N27,$L$4:$L$1231,1),"") -> 1.6989762 | Q27: =+P27-O27 -> 1.6374441 | R27: =+IFERROR(AVERAGEIFS($D$4:$D$1231,$K$4:$K$1231,$N27,$L$4:$L$1231,1),"") -> -4.3805644 | S27: =+R27-O27 -> -4.4420966 | T27: =+IFERROR(AVERAGEIFS($E$4:$E$1231,$K$4:$K$1231,$N27,$L$4:$L$1231,1),"") -> 1.2559609 | U27: =+T27-O27 -> 1.1944287
A28: 46020 | B28: 4.582506 | C28: 5.0868381 | D28: 0.0054212518 | E28: 6.3892345 | G28: =+DAY(A28) -> 29 | H28: 1 | I28: =+MONTH(A28) -> 12 | J28: =+YEAR(A28) -> 2025 | K28: =+DATE(J28,I28,H28) -> 45992 | L28: =IF(AND(G28>=1, G28<=4), 1, 0) -> 0 | N28: 44562 | O28: =+IFERROR(AVERAGEIFS($B$4:$B$1231,$K$4:$K$1231,$N28,$L$4:$L$1231,1),"") -> 1.0139818 | P28: =+IFERROR(AVERAGEIFS($C$4:$C$1231,$K$4:$K$1231,$N28,$L$4:$L$1231,1),"") -> 3.2526276 | Q28: =+P28-O28 -> 2.2386458 | R28: =+IFERROR(AVERAGEIFS($D$4:$D$1231,$K$4:$K$1231,$N28,$L$4:$L$1231,1),"") -> -3.817992 | S28: =+R28-O28 -> -4.8319738 | T28: =+IFERROR(AVERAGEIFS($E$4:$E$1231,$K$4:$K$1231,$N28,$L$4:$L$1231,1),"") -> 1.7930914 | U28: =+T28-O28 -> 0.7791096
... A77: 45946 | B77: 5.0049126 | C77: 7.0514089 | D77: 0.94910974 | E77: 5.4884823 | G77: =+DAY(A77) -> 16 | H77: 1 | I77: =+MONTH(A77) -> 10 | J77: =+YEAR(A77) -> 2025 | K77: =+DATE(J77,I77,H77) -> 45931 | L77: =IF(AND(G77>=1, G77<=4), 1, 0) -> 0 | N77: 46054 | O77: =+IFERROR(AVERAGEIFS($B$4:$B$1231,$K$4:$K$1231,$N77,$L$4:$L$1231,1),"") -> 5.4804618 | P77: =+IFERROR(AVERAGEIFS($C$4:$C$1231,$K$4:$K$1231,$N77,$L$4:$L$1231,1),"") -> 5.2907166 | Q77: =+P77-O77 -> -0.18974513 | R77: =+IFERROR(AVERAGEIFS($D$4:$D$1231,$K$4:$K$1231,$N77,$L$4:$L$1231,1),"") -> 2.839272 | S77: =+R77-O77 -> -2.6411898 | T77: =+IFERROR(AVERAGEIFS($E$4:$E$1231,$K$4:$K$1231,$N77,$L$4:$L$1231,1),"") -> 6.7120809 | U77: =+T77-O77 -> 1.2316191
A78: 45945 | B78: 5.2288558 | C78: 7.0642676 | D78: 1.1682039 | E78: 5.7479702 | G78: =+DAY(A78) -> 15 | H78: 1 | I78: =+MONTH(A78) -> 10 | J78: =+YEAR(A78) -> 2025 | K78: =+DATE(J78,I78,H78) -> 45931 | L78: =IF(AND(G78>=1, G78<=4), 1, 0) -> 0
A79: 45944 | B79: 5.1972159 | C79: 6.9531105 | D79: 0.99137065 | E79: 5.8147374 | G79: =+DAY(A79) -> 14 | H79: 1 | I79: =+MONTH(A79) -> 10 | J79: =+YEAR(A79) -> 2025 | K79: =+DATE(J79,I79,H79) -> 45931 | L79: =IF(AND(G79>=1, G79<=4), 1, 0) -> 0
A80: 45943 | B80: 5.4491957 | C80: 7.2044671 | D80: 1.5352304 | E80: 5.9366394 | G80: =+DAY(A80) -> 13 | H80: 1 | I80: =+MONTH(A80) -> 10 | J80: =+YEAR(A80) -> 2025 | K80: =+DATE(J80,I80,H80) -> 45931 | L80: =IF(AND(G80>=1, G80<=4), 1, 0) -> 0
A81: 45940 | B81: 5.3848874 | C81: 7.0986989 | D81: 1.6256023 | E81: 5.8583523 | G81: =+DAY(A81) -> 10 | H81: 1 | I81: =+MONTH(A81) -> 10 | J81: =+YEAR(A81) -> 2025 | K81: =+DATE(J81,I81,H81) -> 45931 | L81: =IF(AND(G81>=1, G81<=4), 1, 0) -> 0
A82: 45939 | B82: 5.2349237 | C82: 6.8853884 | D82: 1.7169649 | E82: 5.5347124 | G82: =+DAY(A82) -> 9 | H82: 1 | I82: =+MONTH(A82) -> 10 | J82: =+YEAR(A82) -> 2025 | K82: =+DATE(J82,I82,H82) -> 45931 | L82: =IF(AND(G82>=1, G82<=4), 1, 0) -> 0
A83: 45938 | B83: 5.3406999 | C83: 7.045321 | D83: 2.1520495 | E83: 5.5928921 | G83: =+DAY(A83) -> 8 | H83: 1 | I83: =+MONTH(A83) -> 10 | J83: =+YEAR(A83) -> 2025 | K83: =+DATE(J83,I83,H83) -> 45931 | L83: =IF(AND(G83>=1, G83<=4), 1, 0) -> 0
A84: 45937 | B84: 4.8683321 | C84: 6.6178013 | D84: 1.6421464 | E84: 5.1418421 | G84: =+DAY(A84) -> 7 | H84: 1 | I84: =+MONTH(A84) -> 10 | J84: =+YEAR(A84) -> 2025 | K84: =+DATE(J84,I84,H84) -> 45931 | L84: =IF(AND(G84>=1, G84<=4), 1, 0) -> 0
A85: 45936 | B85: 4.8106826 | C85: 6.3520901 | D85: 1.5208331 | E85: 5.206937 | G85: =+DAY(A85) -> 6 | H85: 1 | I85: =+MONTH(A85) -> 10 | J85: =+YEAR(A85) -> 2025 | K85: =+DATE(J85,I85,H85) -> 45931 | L85: =IF(AND(G85>=1, G85<=4), 1, 0) -> 0
A86: 45933 | B86: 5.4114175 | C86: 6.9686433 | D86: 1.8997029 | E86: 5.9378162 | G86: =+DAY(A86) -> 3 | H86: 1 | I86: =+MONTH(A86) -> 10 | J86: =+YEAR(A86) -> 2025 | K86: =+DATE(J86,I86,H86) -> 45931 | L86: =IF(AND(G86>=1, G86<=4), 1, 0) -> 1
A87: 45932 | B87: 5.8161195 | C87: 7.3565016 | D87: 2.2572057 | E87: 6.2307569 | G87: =+DAY(A87) -> 2 | H87: 1 | I87: =+MONTH(A87) -> 10 | J87: =+YEAR(A87) -> 2025 | K87: =+DATE(J87,I87,H87) -> 45931 | L87: =IF(AND(G87>=1, G87<=4), 1, 0) -> 1
A88: 45931 | B88: 5.1935625 | C88: 6.7655979 | D88: 1.6414626 | E88: 5.5872853 | G88: =+DAY(A88) -> 1 | H88: 1 | I88: =+MONTH(A88) -> 10 | J88: =+YEAR(A88) -> 2025 | K88: =+DATE(J88,I88,H88) -> 45931 | L88: =IF(AND(G88>=1, G88<=4), 1, 0) -> 1
...

Sheet HCU_BVU_HSFO - FO CRACK
A1: Description | B1: FO 380 CST 3.5%S FOB Spore Cargo | C1: Dubai Mo01 (NextGen MOC) | E1: Gasoil .001%S (10ppm) FOB Spore vs Gasoil MOPS strip
A2: Currency/UOM | B2: USD/mt | C2: USD/bbl | E2: USD/bbl
A3: Symbol Code | B3: PPXDK00 | C3: PCAAT00 | E3: AAOVD00 | Q3: Only 1-4 of the month
A4: Bate | B4: Close | C4: Close | E4: Diesel Crack | F4: HCU_BVU_HSFO | Q4: HCU_BVU_HSFO | S4: Yes/No
A5: 46055 | B5: 399.2 | C5: 64.99 | D5: =+B5-C5 -> 334.21 | E5: 0.92 | F5: =+E5-D5 -> -333.29 | I5: =+DAY(A5) -> 2 | J5: 1 | K5: =+MONTH(A5) -> 2 | L5: =+YEAR(A5) -> 2026 | N5: =+DATE(L5,K5,J5) -> 46054 | P5: 46054 | Q5: =+AVERAGEIFS($F$5:$F$3568,$N$5:$N$3568,$P5,$S$5:$S$3568,1) -> -333.29 | S5: =IF(AND(I5>=1, I5<=4), 1, 0) -> 1
A6: 46052 | B6: 411.94 | C6: 66.54 | D6: =+B6-C6 -> 345.4 | E6: 0.54 | F6: =+E6-D6 -> -344.86 | I6: =+DAY(A6) -> 30 | J6: 1 | K6: =+MONTH(A6) -> 1 | L6: =+YEAR(A6) -> 2026 | N6: =+DATE(L6,K6,J6) -> 46023 | P6: 46023 | Q6: =+AVERAGEIFS($F$5:$F$3568,$N$5:$N$3568,$P6,$S$5:$S$3568,1) -> -277.11 | S6: =IF(AND(I6>=1, I6<=4), 1, 0) -> 0
A7: 46051 | B7: 412.55 | C7: 66.35 | D7: =+B7-C7 -> 346.2 | E7: 0.52 | F7: =+E7-D7 -> -345.68 | I7: =+DAY(A7) -> 29 | J7: 1 | K7: =+MONTH(A7) -> 1 | L7: =+YEAR(A7) -> 2026 | N7: =+DATE(L7,K7,J7) -> 46023 | P7: 45992 | Q7: =+AVERAGEIFS($F$5:$F$3568,$N$5:$N$3568,$P7,$S$5:$S$3568,1) -> -271.5125 | S7: =IF(AND(I7>=1, I7<=4), 1, 0) -> 0
A8: 46050 | B8: 397.36 | C8: 64.66 | D8: =+B8-C8 -> 332.7 | E8: 0.46 | F8: =+E8-D8 -> -332.24 | I8: =+DAY(A8) -> 28 | J8: 1 | K8: =+MONTH(A8) -> 1 | L8: =+YEAR(A8) -> 2026 | N8: =+DATE(L8,K8,J8) -> 46023 | P8: 45962 | Q8: =+AVERAGEIFS($F$5:$F$3568,$N$5:$N$3568,$P8,$S$5:$S$3568,1) -> -302.305 | S8: =IF(AND(I8>=1, I8<=4), 1, 0) -> 0
A9: 46049 | B9: 382.21 | C9: 62.88 | D9: =+B9-C9 -> 319.33 | E9: 0.27 | F9: =+E9-D9 -> -319.06 | I9: =+DAY(A9) -> 27 | J9: 1 | K9: =+MONTH(A9) -> 1 | L9: =+YEAR(A9) -> 2026 | N9: =+DATE(L9,K9,J9) -> 46023 | P9: 45931 | Q9: =+AVERAGEIFS($F$5:$F$3568,$N$5:$N$3568,$P9,$S$5:$S$3568,1) -> -323.69333 | S9: =IF(AND(I9>=1, I9<=4), 1, 0) -> 0
A10: 46048 | B10: 397.11 | C10: 63.555 | D10: =+B10-C10 -> 333.555 | E10: 0.27 | F10: =+E10-D10 -> -333.285 | I10: =+DAY(A10) -> 26 | J10: 1 | K10: =+MONTH(A10) -> 1 | L10: =+YEAR(A10) -> 2026 | N10: =+DATE(L10,K10,J10) -> 46023 | P10: 45901 | Q10: =+AVERAGEIFS($F$5:$F$3568,$N$5:$N$3568,$P10,$S$5:$S$3568,1) -> -324.20875 | S10: =IF(AND(I10>=1, I10<=4), 1, 0) -> 0
A11: 46045 | B11: 382.05 | C11: 62.27 | D11: =+B11-C11 -> 319.78 | E11: 0.17 | F11: =+E11-D11 -> -319.61 | I11: =+DAY(A11) -> 23 | J11: 1 | K11: =+MONTH(A11) -> 1 | L11: =+YEAR(A11) -> 2026 | N11: =+DATE(L11,K11,J11) -> 46023 | P11: 45870 | Q11: =+AVERAGEIFS($F$5:$F$3568,$N$5:$N$3568,$P11,$S$5:$S$3568,1) -> -334.61 | S11: =IF(AND(I11>=1, I11<=4), 1, 0) -> 0
A12: 46044 | B12: 373.84 | C12: 63.21 | D12: =+B12-C12 -> 310.63 | E12: 0.12 | F12: =+E12-D12 -> -310.51 | I12: =+DAY(A12) -> 22 | J12: 1 | K12: =+MONTH(A12) -> 1 | L12: =+YEAR(A12) -> 2026 | N12: =+DATE(L12,K12,J12) -> 46023 | P12: 45839 | Q12: =+AVERAGEIFS($F$5:$F$3568,$N$5:$N$3568,$P12,$S$5:$S$3568,1) -> -335.96 | S12: =IF(AND(I12>=1, I12<=4), 1, 0) -> 0
A13: 46043 | B13: 362.81 | C13: 62.34 | D13: =+B13-C13 -> 300.47 | E13: 0.11 | F13: =+E13-D13 -> -300.36 | I13: =+DAY(A13) -> 21 | J13: 1 | K13: =+MONTH(A13) -> 1 | L13: =+YEAR(A13) -> 2026 | N13: =+DATE(L13,K13,J13) -> 46023 | P13: 45809 | Q13: =+AVERAGEIFS($F$5:$F$3568,$N$5:$N$3568,$P13,$S$5:$S$3568,1) -> -359.22 | S13: =IF(AND(I13>=1, I13<=4), 1, 0) -> 0
A14: 46042 | B14: 355.92 | C14: 61.8 | D14: =+B14-C14 -> 294.12 | E14: 0.1 | F14: =+E14-D14 -> -294.02 | I14: =+DAY(A14) -> 20 | J14: 1 | K14: =+MONTH(A14) -> 1 | L14: =+YEAR(A14) -> 2026 | N14: =+DATE(L14,K14,J14) -> 46023 | P14: 45778 | Q14: =+AVERAGEIFS($F$5:$F$3568,$N$5:$N$3568,$P14,$S$5:$S$3568,1) -> -335.49 | S14: =IF(AND(I14>=1, I14<=4), 1, 0) -> 0
A15: 46041 | B15: 359.96 | C15: 61.95 | D15: =+B15-C15 -> 298.01 | E15: 0.11 | F15: =+E15-D15 -> -297.9 | I15: =+DAY(A15) -> 19 | J15: 1 | K15: =+MONTH(A15) -> 1 | L15: =+YEAR(A15) -> 2026 | N15: =+DATE(L15,K15,J15) -> 46023 | P15: 45748 | Q15: =+AVERAGEIFS($F$5:$F$3568,$N$5:$N$3568,$P15,$S$5:$S$3568,1) -> -367.135 | S15: =IF(AND(I15>=1, I15<=4), 1, 0) -> 0
A16: 46038 | B16: 358.05 | C16: 62.28 | D16: =+B16-C16 -> 295.77 | E16: 0.07 | F16: =+E16-D16 -> -295.7 | I16: =+DAY(A16) -> 16 | J16: 1 | K16: =+MONTH(A16) -> 1 | L16: =+YEAR(A16) -> 2026 | N16: =+DATE(L16,K16,J16) -> 46023 | P16: 45717 | Q16: =+AVERAGEIFS($F$5:$F$3568,$N$5:$N$3568,$P16,$S$5:$S$3568,1) -> -390.87 | S16: =IF(AND(I16>=1, I16<=4), 1, 0) -> 0
... A450: 45408 | B450: 509.4 | C450: 88.96 | D450: =+B450-C450 -> 420.44 | E450: 0 | F450: =+E450-D450 -> -420.44 | I450: =+DAY(A450) -> 26 | J450: 1 | K450: =+MONTH(A450) -> 4 | L450: =+YEAR(A450) -> 2024 | N450: =+DATE(L450,K450,J450) -> 45383 | P450: 32509 | Q450: =+AVERAGEIFS($F$5:$F$3568,$N$5:$N$3568,$P450,$S$5:$S$3568,1) -> #DIV/0! | S450: =IF(AND(I450>=1, I450<=4), 1, 0) -> 0
A451: 45407 | B451: 506 | C451: 88.6 | D451: =+B451-C451 -> 417.4 | E451: 0.04 | F451: =+E451-D451 -> -417.36 | I451: =+DAY(A451) -> 25 | J451: 1 | K451: =+MONTH(A451) -> 4 | L451: =+YEAR(A451) -> 2024 | N451: =+DATE(L451,K451,J451) -> 45383 | S451: =IF(AND(I451>=1, I451<=4), 1, 0) -> 0
A452: 45406 | B452: 496.78 | C452: 88.85 | D452: =+B452-C452 -> 407.93 | E452: -0.04 | F452: =+E452-D452 -> -407.97 | I452: =+DAY(A452) -> 24 | J452: 1 | K452: =+MONTH(A452) -> 4 | L452: =+YEAR(A452) -> 2024 | N452: =+DATE(L452,K452,J452) -> 45383 | S452: =IF(AND(I452>=1, I452<=4), 1, 0) -> 0
A453: 45405 | B453: 497.75 | C453: 88.45 | D453: =+B453-C453 -> 409.3 | E453: -0.01 | F453: =+E453-D453 -> -409.31 | I453: =+DAY(A453) -> 23 | J453: 1 | K453: =+MONTH(A453) -> 4 | L453: =+YEAR(A453) -> 2024 | N453: =+DATE(L453,K453,J453) -> 45383 | S453: =IF(AND(I453>=1, I453<=4), 1, 0) -> 0
A454: 45404 | B454: 489.36 | C454: 86.395 | D454: =+B454-C454 -> 402.965 | E454: 0.12 | F454: =+E454-D454 -> -402.845 | I454: =+DAY(A454) -> 22 | J454: 1 | K454: =+MONTH(A454) -> 4 | L454: =+YEAR(A454) -> 2024 | N454: =+DATE(L454,K454,J454) -> 45383 | S454: =IF(AND(I454>=1, I454<=4), 1, 0) -> 0
A455: 45401 | B455: 499.21 | C455: 87.69 | D455: =+B455-C455 -> 411.52 | E455: 0.22 | F455: =+E455-D455 -> -411.3 | I455: =+DAY(A455) -> 19 | J455: 1 | K455: =+MONTH(A455) -> 4 | L455: =+YEAR(A455) -> 2024 | N455: =+DATE(L455,K455,J455) -> 45383 | S455: =IF(AND(I455>=1, I455<=4), 1, 0) -> 0
A456: 45400 | B456: 495.32 | C456: 87.44 | D456: =+B456-C456 -> 407.88 | E456: 0.01 | F456: =+E456-D456 -> -407.87 | I456: =+DAY(A456) -> 18 | J456: 1 | K456: =+MONTH(A456) -> 4 | L456: =+YEAR(A456) -> 2024 | N456: =+DATE(L456,K456,J456) -> 45383 | S456: =IF(AND(I456>=1, I456<=4), 1, 0) -> 0
A457: 45399 | B457: 500.5 | C457: 90.05 | D457: =+B457-C457 -> 410.45 | E457: -0.03 | F457: =+E457-D457 -> -410.48 | I457: =+DAY(A457) -> 17 | J457: 1 | K457: =+MONTH(A457) -> 4 | L457: =+YEAR(A457) -> 2024 | N457: =+DATE(L457,K457,J457) -> 45383 | S457: =IF(AND(I457>=1, I457<=4), 1, 0) -> 0
A458: 45398 | B458: 500.33 | C458: 90.25 | D458: =+B458-C458 -> 410.08 | E458: -0.13 | F458: =+E458-D458 -> -410.21 | I458: =+DAY(A458) -> 16 | J458: 1 | K458: =+MONTH(A458) -> 4 | L458: =+YEAR(A458) -> 2024 | N458: =+DATE(L458,K458,J458) -> 45383 | S458: =IF(AND(I458>=1, I458<=4), 1, 0) -> 0
A459: 45397 | B459: 490.35 | C459: 89.54 | D459: =+B459-C459 -> 400.81 | E459: -0.14 | F459: =+E459-D459 -> -400.95 | I459: =+DAY(A459) -> 15 | J459: 1 | K459: =+MONTH(A459) -> 4 | L459: =+YEAR(A459) -> 2024 | N459: =+DATE(L459,K459,J459) -> 45383 | S459: =IF(AND(I459>=1, I459<=4), 1, 0) -> 0
A460: 45394 | B460: 492.18 | C460: 90.51 | D460: =+B460-C460 -> 401.67 | E460: -0.14 | F460: =+E460-D460 -> -401.81 | I460: =+DAY(A460) -> 12 | J460: 1 | K460: =+MONTH(A460) -> 4 | L460: =+YEAR(A460) -> 2024 | N460: =+DATE(L460,K460,J460) -> 45383 | S460: =IF(AND(I460>=1, I460<=4), 1, 0) -> 0
A461: 45393 | B461: 489.81 | C461: 90.89 | D461: =+B461-C461 -> 398.92 | E461: -0.09 | F461: =+E461-D461 -> -399.01 | I461: =+DAY(A461) -> 11 | J461: 1 | K461: =+MONTH(A461) -> 4 | L461: =+YEAR(A461) -> 2024 | N461: =+DATE(L461,K461,J461) -> 45383 | S461: =IF(AND(I461>=1, I461<=4), 1, 0) -> 0
